Workbook

Sheet RAW
A1: Invoice Number | B1: Quantity | C1: Retail Price | D1: Disc Description | E1: Selling Price | F1: Document Data | G1: Item Code | H1: Store of the document | I1: Document Index | J1: Disc - Tax excl. amount | K1: Disc - Tax excl. amount in currency | L1: Disc - Tax incl. amount | M1: Disc - Tax incl. amount in currency | N1: Disc line type | O1: Doc number | P1: Line number | Q1: Order Number | R1: Origin of discount | S1: Ranking number | T1: Line ranking number | U1: Disc percentage | V1: Disc line stub | W1: Disc basis | X1: Disc basis price - currency | Y1: Sales Condition | Z1: Item Identiier | AA1: Register of the line | AB1: Warehouse Doc | AC1: Store - document line | AD1: Brand | AE1: Dept | AF1: Segment | AG1: Countermark supplier | AH1: Line Description | AI1: Doc lin sales representative | AJ1: Third party of the line | AK1: Item type line | AL1: Type of line | AM1: Shipping status for items | AN1: Doc of consigned items | AO1: Vendor Style Code | AP1: Add item description | AQ1: Dimension | AR1: Develop code | AS1: Item barcode | AT1: Colour | AU1: Size | AV1: Dimension 3 | AW1: Dimension 4 | AX1: Dimension 5 | AY1: Promo Type
A2: 29057 | B2: 1 | C2: 1990000 | D2: Special Offer | E2: 1253700 | F2: 46292 | G2: FIRDA | H2: M310 | I2: 0 | J2: 125496 | K2: 125496 | L2: 139300 | M2: 139300 | N2: FFO | O2: 29057 | P2: 2 | Q2: 2 | R2: 006 | S2: 2 | T2: 0 | U2: 10 | V2: M310 | W2: 1393000 | X2: 1393000 | Y2: 7059 | Z2: FIRDA 003007 X | AB2: M310 | AC2: M310 | AD2: EB | AE2: LDS | AF2: SHS | AH2: EVERBEST LADIES SHOES BLACK 40 | AI2: 17294 | AJ2: WLK999 | AL2: ART | AO2: JZ | AS2: 996902067294 | AT2: 003 | AU2: 007 | AY2: ADD 10%
A3: 29057 | B3: 1 | C3: 1790000 | D3: Special Offer | E3: 1127700 | F3: 46292 | G3: DERBY | H3: M310 | I3: 0 | J3: 112883 | K3: 112883 | L3: 125300 | M3: 125300 | N3: FFO | O3: 29057 | P3: 1 | Q3: 1 | R3: 006 | S3: 2 | T3: 0 | U3: 10 | V3: M310 | W3: 1253000 | X3: 1253000 | Y3: 7059 | Z3: DERBY 001008 X | AB3: M310 | AC3: M310 | AD3: EB | AE3: LDS | AF3: SHS | AH3: EVERBEST LADIES SHOES ALMOND 39 | AI3: 17294 | AJ3: WLK999 | AL3: ART | AO3: JZ | AS3: 996902037700 | AT3: 001 | AU3: 008 | AY3: ADD 10%
A4: 29056 | B4: 1 | C4: 1690000 | D4: Special Offer | E4: 1064700 | F4: 46292 | G4: EFINE | H4: M310 | I4: 0 | J4: 106577 | K4: 106577 | L4: 118300 | M4: 118300 | N4: FFO | O4: 29056 | P4: 2 | Q4: 2 | R4: 006 | S4: 2 | T4: 0 | U4: 10 | V4: M310 | W4: 1183000 | X4: 1183000 | Y4: 7059 | Z4: EFINE 003001 X | AB4: M310 | AC4: M310 | AD4: EB | AE4: LDS | AF4: SHS | AH4: EVERBEST LADIES SHOES BLACK 37 | AI4: 17288 | AJ4: WLK999 | AL4: ART | AO4: KH | AS4: 996902079892 | AT4: 003 | AU4: 001 | AY4: ADD 10%
A5: 29056 | B5: 1 | C5: 1690000 | D5: Special Offer | E5: 1064700 | F5: 46292 | G5: EFINE | H5: M310 | I5: 0 | J5: 106577 | K5: 106577 | L5: 118300 | M5: 118300 | N5: FFO | O5: 29056 | P5: 1 | Q5: 1 | R5: 006 | S5: 2 | T5: 0 | U5: 10 | V5: M310 | W5: 1183000 | X5: 1183000 | Y5: 7059 | Z5: EFINE 00H005 X | AB5: M310 | AC5: M310 | AD5: EB | AE5: LDS | AF5: SHS | AH5: EVERBEST LADIES SHOES LIGHT BLUE 36 | AI5: 17288 | AJ5: WLK999 | AL5: ART | AO5: KH | AS5: 996902079898 | AT5: 00H | AU5: 005 | AY5: ADD 10%
A6: 29050 | B6: 1 | C6: 2990000 | D6: Special Offer | E6: 1345500 | F6: 46291 | G6: OLETHA | H6: M310 | I6: 0 | J6: 134685 | K6: 134685 | L6: 149500 | M6: 149500 | N6: FFO | O6: 29050 | P6: 1 | Q6: 1 | R6: 006 | S6: 2 | T6: 0 | U6: 10 | V6: M310 | W6: 1495000 | X6: 1495000 | Y6: 7059 | Z6: OLETHA 002001 X | AB6: M310 | AC6: M310 | AD6: EB | AE6: LDS | AF6: BAG | AH6: EVERBEST LADIES HANDBAGS BEIGE FREE SIZE | AI6: 17286 | AJ6: WLK999 | AL6: ART | AO6: HJX | AQ6: 25(L) x 105(H) x 25(W) cm | AS6: 996902072727 | AT6: 002 | AU6: 001 | AY6: ADD 10%
A7: 29050 | B7: 1 | C7: 2390000 | D7: Special Offer | E7: 1075500 | F7: 46291 | G7: OMYRA | H7: M310 | I7: 0 | J7: 107658 | K7: 107658 | L7: 119500 | M7: 119500 | N7: FFO | O7: 29050 | P7: 2 | Q7: 2 | R7: 006 | S7: 2 | T7: 0 | U7: 10 | V7: M310 | W7: 1195000 | X7: 1195000 | Y7: 7059 | Z7: OMYRA 003001 X | AB7: M310 | AC7: M310 | AD7: EB | AE7: LDS | AF7: BAG | AH7: EVERBEST LADIES HANDBAGS BLACK FREE SIZE | AI7: 17286 | AJ7: WLK999 | AL7: ART | AO7: HBYY | AQ7: 21(L) x 7(H) x 14(W) cm | AS7: 996902072729 | AT7: 003 | AU7: 001 | AY7: ADD 10%
A8: 29052 | B8: 1 | C8: 1890000 | D8: Special Offer | E8: 850500 | F8: 46291 | G8: LIVERA | H8: M310 | I8: 0 | J8: 85135 | K8: 85135 | L8: 94500 | M8: 94500 | N8: FFO | O8: 29052 | P8: 1 | Q8: 1 | R8: 006 | S8: 2 | T8: 0 | U8: 10 | V8: M310 | W8: 945000 | X8: 945000 | Y8: 7059 | Z8: LIVERA 003001 X | AB8: M310 | AC8: M310 | AD8: EB | AE8: LDS | AF8: SHS | AH8: EVERBEST LADIES SHOES BLACK 37 | AI8: 17288 | AJ8: WLK999 | AL8: ART | AO8: HU | AS8: 996902070742 | AT8: 003 | AU8: 001 | AY8: ADD 10%
A9: 29052 | B9: 1 | C9: 1790000 | D9: Special Offer | E9: 1127700 | F9: 46291 | G9: DERBY | H9: M310 | I9: 0 | J9: 112883 | K9: 112883 | L9: 125300 | M9: 125300 | N9: FFO | O9: 29052 | P9: 2 | Q9: 2 | R9: 006 | S9: 2 | T9: 0 | U9: 10 | V9: M310 | W9: 1253000 | X9: 1253000 | Y9: 7059 | Z9: DERBY 001002 X | AB9: M310 | AC9: M310 | AD9: EB | AE9: LDS | AF9: SHS | AH9: EVERBEST LADIES SHOES ALMOND 35 | AI9: 17288 | AJ9: WLK999 | AL9: ART | AO9: JZ | AS9: 996902037696 | AT9: 001 | AU9: 002 | AY9: ADD 10%
A10: 21891 | B10: 1 | C10: 1690000 | D10: Special Offer | E10: 718250 | F10: 46289 | G10: HANANIAH | H10: M010 | I10: 0 | J10: 114189 | K10: 114189 | L10: 126750 | M10: 126750 | N10: FFO | O10: 21891 | P10: 3 | Q10: 3 | R10: 006 | S10: 2 | T10: 0 | U10: 15 | V10: M010 | W10: 845000 | X10: 845000 | Y10: 7059 | Z10: HANANIAH 003003 X | AB10: M010 | AC10: M010 | AD10: EB | AE10: LDS | AF10: SHS | AH10: EVERBEST LADIES SHOES BLACK 38 | AI10: 15493 | AJ10: WLK999 | AL10: ART | AO10: BTN | AS10: 996902076124 | AT10: 003 | AU10: 003 | AY10: ADD 15%
A11: 21891 | B11: 1 | C11: 1890000 | D11: Special Offer | E11: 1124550 | F11: 46289 | G11: NAVELLA | H11: M010 | I11: 0 | J11: 178784 | K11: 178784 | L11: 198450 | M11: 198450 | N11: FFO | O11: 21891 | P11: 1 | Q11: 1 | R11: 006 | S11: 2 | T11: 0 | U11: 15 | V11: M010 | W11: 1323000 | X11: 1323000 | Y11: 7059 | Z11: NAVELLA 003002 X | AB11: M010 | AC11: M010 | AD11: EB | AE11: LDS | AF11: SHS | AH11: EVERBEST LADIES SHOES BLACK 35 | AI11: 15493 | AJ11: WLK999 | AL11: ART | AO11: HU | AS11: 996902081357 | AT11: 003 | AU11: 002 | AY11: ADD 15%
A12: 21891 | B12: 1 | C12: 1690000 | D12: Special Offer | E12: 718250 | F12: 46289 | G12: HANANIAH | H12: M010 | I12: 0 | J12: 114189 | K12: 114189 | L12: 126750 | M12: 126750 | N12: FFO | O12: 21891 | P12: 2 | Q12: 2 | R12: 006 | S12: 2 | T12: 0 | U12: 15 | V12: M010 | W12: 845000 | X12: 845000 | Y12: 7059 | Z12: HANANIAH 003001 X | AB12: M010 | AC12: M010 | AD12: EB | AE12: LDS | AF12: SHS | AH12: EVERBEST LADIES SHOES BLACK 37 | AI12: 15493 | AJ12: WLK999 | AL12: ART | AO12: BTN | AS12: 996902076123 | AT12: 003 | AU12: 001 | AY12: ADD 15%
A13: 21871 | B13: 1 | C13: 1790000 | D13: Special Offer | E13: 805500 | F13: 46285 | G13: NALANA | H13: M010 | I13: 0 | J13: 80631 | K13: 80631 | L13: 89500 | M13: 89500 | N13: FFO | O13: 21871 | P13: 2 | Q13: 2 | R13: 006 | S13: 2 | T13: 0 | U13: 10 | V13: M010 | W13: 895000 | X13: 895000 | Y13: 7059 | Z13: NALANA 002005 X | AB13: M010 | AC13: M010 | AD13: EB | AE13: LDS | AF13: SHS | AH13: EVERBEST LADIES SHOES BEIGE 36 | AI13: 16625 | AJ13: WLK999 | AL13: ART | AO13: HU | AS13: 996902073402 | AT13: 002 | AU13: 005 | AY13: ADD 10%
A14: 21871 | B14: 1 | C14: 1890000 | D14: Special Offer | E14: 1020600 | F14: 46285 | G14: JIANNI | H14: M010 | I14: 0 | J14: 102162 | K14: 102162 | L14: 113400 | M14: 113400 | N14: FFO | O14: 21871 | P14: 1 | Q14: 1 | R14: 006 | S14: 2 | T14: 0 | U14: 10 | V14: M010 | W14: 1134000 | X14: 1134000 | Y14: 7059 | Z14: JIANNI 005003 X | AB14: M010 | AC14: M010 | AD14: EB | AE14: LDS | AF14: SHS | AH14: EVERBEST LADIES SHOES BRONZE 38 | AI14: 16625 | AJ14: WLK999 | AL14: ART | AO14: HU | AS14: 996902069259 | AT14: 005 | AU14: 003 | AY14: ADD 10%
A15: 29028 | B15: 1 | C15: 1790000 | D15: Special Offer | E15: 805500 | F15: 46285 | G15: PATRINA | H15: M310 | I15: 0 | J15: 80631 | K15: 80631 | L15: 89500 | M15: 89500 | N15: FFO | O15: 29028 | P15: 2 | Q15: 2 | R15: 006 | S15: 2 | T15: 0 | U15: 10 | V15: M310 | W15: 895000 | X15: 895000 | Y15: 7059 | Z15: PATRINA 00M001 X | AB15: M310 | AC15: M310 | AD15: EB | AE15: LDS | AF15: SHS | AH15: EVERBEST LADIES SHOES LIGHT YELLOW 37 | AI15: 17294 | AJ15: WLK999 | AL15: ART | AO15: KH | AS15: 996902074117 | AT15: 00M | AU15: 001 | AY15: ADD 10%
A16: 36485 | B16: 1 | C16: 1890000 | D16: Special Offer | E16: 1190700 | F16: 46285 | G16: GAVESHA | H16: M730 | I16: 0 | J16: 119189 | K16: 119189 | L16: 132300 | M16: 132300 | N16: FFO | O16: 36485 | P16: 2 | Q16: 6 | R16: 006 | S16: 2 | T16: 0 | U16: 10 | V16: M730 | W16: 1323000 | X16: 1323000 | Y16: 7059 | Z16: GAVESHA 003001 X | AB16: M730 | AC16: M730 | AD16: EB | AE16: LDS | AF16: BAG | AH16: EVERBEST LADIES BAGS BLACK FREE SIZE | AI16: 17096 | AJ16: WLK999 | AL16: ART | AO16: HBYY | AS16: 996902081883 | AT16: 003 | AU16: 001 | AY16: ADD 10%
A17: 36485 | B17: 1 | C17: 2490000 | D17: Special Offer | E17: 1568700 | F17: 46285 | G17: INHA | H17: M730 | I17: 0 | J17: 157027 | K17: 157027 | L17: 174300 | M17: 174300 | N17: FFO | O17: 36485 | P17: 1 | Q17: 4 | R17: 006 | S17: 2 | T17: 0 | U17: 10 | V17: M730 | W17: 1743000 | X17: 1743000 | Y17: 7059 | Z17: INHA 003001 X | AB17: M730 | AC17: M730 | AD17: EB | AE17: LDS | AF17: BAG | AH17: EVERBEST LADIES BAGS BLACK FREE SIZE | AI17: 17096 | AJ17: WLK999 | AL17: ART | AS17: 996902080351 | AT17: 003 | AU17: 001 | AY17: ADD 10%
A18: 36489 | B18: 1 | C18: 1790000 | D18: Special Offer | E18: 760750 | F18: 46285 | G18: ARDERE | H18: M730 | I18: 0 | J18: 120946 | K18: 120946 | L18: 134250 | M18: 134250 | N18: FFO | O18: 36489 | P18: 2 | Q18: 2 | R18: 006 | S18: 2 | T18: 0 | U18: 15 | V18: M730 | W18: 895000 | X18: 895000 | Y18: 7059 | Z18: ARDERE 011008 X | AB18: M730 | AC18: M730 | AD18: EB | AE18: LDS | AF18: SHS | AH18: EVERBEST LADIES SHOES TAUPE 39 | AI18: 16927 | AJ18: WLK999 | AL18: ART | AO18: JZ | AS18: 996902071413 | AT18: 011 | AU18: 008 | AY18: ADD 15%
A19: 36489 | B19: 1 | C19: 1790000 | D19: Special Offer | E19: 760750 | F19: 46285 | G19: FURREY | H19: M730 | I19: 0 | J19: 120946 | K19: 120946 | L19: 134250 | M19: 134250 | N19: FFO | O19: 36489 | P19: 3 | Q19: 3 | R19: 006 | S19: 2 | T19: 0 | U19: 15 | V19: M730 | W19: 895000 | X19: 895000 | Y19: 7059 | Z19: FURREY 00Z005 X | AB19: M730 | AC19: M730 | AD19: EB | AE19: LDS | AF19: SHS | AH19: EVERBEST LADIES SHOES TAN 36 | AI19: 16927 | AJ19: WLK999 | AL19: ART | AO19: HU | AS19: 996902066782 | AT19: 00Z | AU19: 005 | AY19: ADD 15%
A20: 29013 | B20: 1 | C20: 1690000 | D20: Special Offer | E20: 912600 | F20: 46282 | G20: BRAYLEN | H20: M310 | I20: 0 | J20: 91351 | K20: 91351 | L20: 101400 | M20: 101400 | N20: FFO | O20: 29013 | P20: 1 | Q20: 1 | R20: 006 | S20: 2 | T20: 0 | U20: 10 | V20: M310 | W20: 1014000 | X20: 1014000 | Y20: 7059 | Z20: BRAYLEN 003007 X | AB20: M310 | AC20: M310 | AD20: EB | AE20: MEN | AF20: SHS | AH20: EVERBEST MEN SHOES BLACK 40 | AI20: 15443 | AJ20: WLK999 | AL20: ART | AO20: DB | AS20: 996902068024 | AT20: 003 | AU20: 007 | AY20: ADD 10%
A21: 36461 | B21: 1 | C21: 2290000 | D21: Special Offer | E21: 1442700 | F21: 46281 | G21: EFRA | H21: M730 | I21: 0 | J21: 144414 | K21: 144414 | L21: 160300 | M21: 160300 | N21: FFO | O21: 36461 | P21: 1 | Q21: 1 | R21: 006 | S21: 2 | T21: 0 | U21: 10 | V21: M730 | W21: 1603000 | X21: 1603000 | Y21: 7059 | Z21: EFRA 003001 X | AB21: M730 | AC21: M730 | AD21: EB | AE21: LDS | AF21: BAG | AH21: EVERBEST LADIES HANDBAGS BLACK FREE SIZE | AI21: 17170 | AJ21: WLK999 | AL21: ART | AS21: 996902078230 | AT21: 003 | AU21: 001 | AY21: ADD 10%
A22: 36457 | B22: 1 | C22: 1790000 | D22: Special Offer | E22: 805500 | F22: 46279 | G22: FERBIE | H22: M730 | I22: 0 | J22: 80631 | K22: 80631 | L22: 89500 | M22: 89500 | N22: FFO | O22: 36457 | P22: 2 | Q22: 2 | R22: 006 | S22: 2 | T22: 0 | U22: 10 | V22: M730 | W22: 895000 | X22: 895000 | Y22: 7059 | Z22: FERBIE 003005 X | AB22: M730 | AC22: M730 | AD22: EB | AE22: LDS | AF22: SHS | AH22: EVERBEST LADIES SHOES BLACK 36 | AI22: 16927 | AJ22: WLK999 | AL22: ART | AO22: JZ | AS22: 996902067566 | AT22: 003 | AU22: 005 | AY22: ADD 10%
A23: 36457 | B23: 1 | C23: 1790000 | D23: Special Offer | E23: 805500 | F23: 46279 | G23: FERBIE | H23: M730 | I23: 0 | J23: 80631 | K23: 80631 | L23: 89500 | M23: 89500 | N23: FFO | O23: 36457 | P23: 1 | Q23: 1 | R23: 006 | S23: 2 | T23: 0 | U23: 10 | V23: M730 | W23: 895000 | X23: 895000 | Y23: 7059 | Z23: FERBIE 003002 X | AB23: M730 | AC23: M730 | AD23: EB | AE23: LDS | AF23: SHS | AH23: EVERBEST LADIES SHOES BLACK 35 | AI23: 16927 | AJ23: WLK999 | AL23: ART | AO23: JZ | AS23: 996902067565 | AT23: 003 | AU23: 002 | AY23: ADD 10%
A24: 36447 | B24: 1 | C24: 1790000 | D24: Special Offer | E24: 1065050 | F24: 46277 | G24: MARCUS | H24: M730 | I24: 0 | J24: 169324 | K24: 169324 | L24: 187950 | M24: 187950 | N24: FFO | O24: 36447 | P24: 3 | Q24: 4 | R24: 006 | S24: 2 | T24: 0 | U24: 15 | V24: M730 | W24: 1253000 | X24: 1253000 | Y24: 7059 | Z24: MARCUS 00P001 X | AB24: M730 | AC24: M730 | AD24: EB | AE24: MEN | AF24: BAG | AH24: EVERBEST MEN BAGS NAVY FREE SIZE | AI24: 16927 | AJ24: WLK999 | AL24: ART | AO24: EVG | AS24: 996902053384 | AT24: 00P | AU24: 001 | AY24: ADD 15%
A25: 29006 | B25: 1 | C25: 2390000 | D25: Special Offer | E25: 1015750 | F25: 46277 | G25: OMYRA | H25: M310 | I25: 0 | J25: 161486 | K25: 161486 | L25: 179250 | M25: 179250 | N25: FFO | O25: 29006 | P25: 3 | Q25: 3 | R25: 006 | S25: 2 | T25: 0 | U25: 15 | V25: M310 | W25: 1195000 | X25: 1195000 | Y25: 7059 | Z25: OMYRA 002001 X | AB25: M310 | AC25: M310 | AD25: EB | AE25: LDS | AF25: BAG | AH25: EVERBEST LADIES HANDBAGS BEIGE FREE SIZE | AI25: 17286 | AJ25: WLK999 | AL25: ART | AO25: HBYY | AQ25: 21(L) x 7(H) x 14(W) cm | AS25: 996902072730 | AT25: 002 | AU25: 001 | AY25: ADD 15%
A26: 29006 | B26: 1 | C26: 1890000 | D26: Special Offer | E26: 803250 | F26: 46277 | G26: TYANNA | H26: M310 | I26: 0 | J26: 127703 | K26: 127703 | L26: 141750 | M26: 141750 | N26: FFO | O26: 29006 | P26: 1 | Q26: 1 | R26: 006 | S26: 2 | T26: 0 | U26: 15 | V26: M310 | W26: 945000 | X26: 945000 | Y26: 7059 | Z26: TYANNA 003003 X | AB26: M310 | AC26: M310 | AD26: EB | AE26: LDS | AF26: SHS | AH26: EVERBEST LADIES SHOES BLACK 38 | AI26: 17286 | AJ26: WLK999 | AL26: ART | AO26: JZ | AS26: 996902075042 | AT26: 003 | AU26: 003 | AY26: ADD 15%
A27: 36444 | B27: 1 | C27: 1990000 | D27: Special Offer | E27: 1184050 | F27: 46276 | G27: FIRDA | H27: M730 | I27: 0 | J27: 188243 | K27: 188243 | L27: 208950 | M27: 208950 | N27: FFO | O27: 36444 | P27: 3 | Q27: 3 | R27: 006 | S27: 2 | T27: 0 | U27: 15 | V27: M730 | W27: 1393000 | X27: 1393000 | Y27: 7059 | Z27: FIRDA 003002 X | AB27: M730 | AC27: M730 | AD27: EB | AE27: LDS | AF27: SHS | AH27: EVERBEST LADIES SHOES BLACK 35 | AI27: 16927 | AJ27: WLK999 | AL27: ART | AO27: JZ | AS27: 996902067289 | AT27: 003 | AU27: 002 | AY27: ADD 15%
A28: 36444 | B28: 1 | C28: 1690000 | D28: Special Offer | E28: 718250 | F28: 46276 | G28: MOSS | H28: M730 | I28: 0 | J28: 114189 | K28: 114189 | L28: 126750 | M28: 126750 | N28: FFO | O28: 36444 | P28: 1 | Q28: 1 | R28: 006 | S28: 2 | T28: 0 | U28: 15 | V28: M730 | W28: 845000 | X28: 845000 | Y28: 7059 | Z28: MOSS 003008 X | AB28: M730 | AC28: M730 | AD28: EB | AE28: MEN | AF28: SHS | AH28: EVERBEST MEN SHOES BLACK 39 | AI28: 16927 | AJ28: WLK999 | AL28: ART | AO28: SBL | AS28: 996902069191 | AT28: 003 | AU28: 008 | AY28: ADD 15%
A29: 29004 | B29: 1 | C29: 1890000 | D29: Special Offer | E29: 850500 | F29: 46276 | G29: NALI | H29: M310 | I29: 0 | J29: 85135 | K29: 85135 | L29: 94500 | M29: 94500 | N29: FFO | O29: 29004 | P29: 1 | Q29: 1 | R29: 006 | S29: 2 | T29: 0 | U29: 10 | V29: M310 | W29: 945000 | X29: 945000 | Y29: 7059 | Z29: NALI 002001 X | AB29: M310 | AC29: M310 | AD29: EB | AE29: LDS | AF29: SHS | AH29: EVERBEST LADIES SHOES BEIGE 37 | AI29: 17286 | AJ29: WLK999 | AL29: ART | AO29: HU | AS29: 996902073620 | AT29: 002 | AU29: 001 | AY29: ADD 10%
A30: 5420 | B30: 1 | C30: 1890000 | D30: Special Offer | E30: 1124550 | F30: 46275 | G30: GAVESHA | H30: M190 | I30: 0 | J30: 178784 | K30: 178784 | L30: 198450 | M30: 198450 | N30: FFO | O30: 5420 | P30: 6 | Q30: 6 | R30: 006 | S30: 2 | T30: 0 | U30: 15 | V30: M190 | W30: 1323000 | X30: 1323000 | Y30: 7059 | Z30: GAVESHA 001001 X | AB30: M190 | AC30: M190 | AD30: EB | AE30: LDS | AF30: BAG | AH30: EVERBEST LADIES BAGS ALMOND FREE SIZE | AI30: 15967 | AJ30: WLK999 | AL30: ART | AO30: HBYY | AS30: 996902081884 | AT30: 001 | AU30: 001 | AY30: ADD 15%
A31: 5420 | B31: 1 | C31: 1690000 | D31: Special Offer | E31: 1005550 | F31: 46275 | G31: CAILIN | H31: M190 | I31: 0 | J31: 159865 | K31: 159865 | L31: 177450 | M31: 177450 | N31: FFO | O31: 5420 | P31: 5 | Q31: 5 | R31: 006 | S31: 2 | T31: 0 | U31: 15 | V31: M190 | W31: 1183000 | X31: 1183000 | Y31: 7059 | Z31: CAILIN 003003 X | AB31: M190 | AC31: M190 | AD31: EB | AE31: LDS | AF31: SHS | AH31: EVERBEST LADIES SHOES BLACK 38 | AI31: 15967 | AJ31: WLK999 | AL31: ART | AO31: JZ | AS31: 996902079947 | AT31: 003 | AU31: 003 | AY31: ADD 15%
A32: 5420 | B32: 1 | C32: 1590000 | D32: Special Offer | E32: 675750 | F32: 46275 | G32: DANERA | H32: M190 | I32: 0 | J32: 107432 | K32: 107432 | L32: 119250 | M32: 119250 | N32: FFO | O32: 5420 | P32: 3 | Q32: 3 | R32: 006 | S32: 2 | T32: 0 | U32: 15 | V32: M190 | W32: 795000 | X32: 795000 | Y32: 7059 | Z32: DANERA 00P003 X | AB32: M190 | AC32: M190 | AD32: EB | AE32: LDS | AF32: SHS | AH32: EVERBEST LADIES SHOES NAVY 38 | AI32: 15967 | AJ32: WLK999 | AL32: ART | AO32: BTN | AS32: 996902064530 | AT32: 00P | AU32: 003 | AY32: ADD 15%
A33: 5420 | B33: 1 | C33: 1690000 | D33: Special Offer | E33: 718250 | F33: 46275 | G33: JASIC | H33: M190 | I33: 0 | J33: 114189 | K33: 114189 | L33: 126750 | M33: 126750 | N33: FFO | O33: 5420 | P33: 4 | Q33: 4 | R33: 006 | S33: 2 | T33: 0 | U33: 15 | V33: M190 | W33: 845000 | X33: 845000 | Y33: 7059 | Z33: JASIC 011001 X | AB33: M190 | AC33: M190 | AD33: EB | AE33: LDS | AF33: SHS | AH33: EVERBEST LADIES SHOES TAUPE 37 | AI33: 15967 | AJ33: WLK999 | AL33: ART | AO33: KH | AS33: 996902069471 | AT33: 011 | AU33: 001 | AY33: ADD 15%
A34: 5420 | B34: 1 | C34: 1690000 | D34: Special Offer | E34: 1005550 | F34: 46275 | G34: CESSEL | H34: M190 | I34: 0 | J34: 159865 | K34: 159865 | L34: 177450 | M34: 177450 | N34: FFO | O34: 5420 | P34: 2 | Q34: 2 | R34: 006 | S34: 2 | T34: 0 | U34: 15 | V34: M190 | W34: 1183000 | X34: 1183000 | Y34: 7059 | Z34: CESSEL 003001 X | AB34: M190 | AC34: M190 | AD34: EB | AE34: LDS | AF34: SHS | AH34: EVERBEST LADIES SHOES BLACK 37 | AI34: 15967 | AJ34: WLK999 | AL34: ART | AO34: JZ | AS34: 996902079780 | AT34: 003 | AU34: 001 | AY34: ADD 15%
A35: 5420 | B35: 1 | C35: 1690000 | D35: Special Offer | E35: 1005550 | F35: 46275 | G35: CESSEL | H35: M190 | I35: 0 | J35: 159865 | K35: 159865 | L35: 177450 | M35: 177450 | N35: FFO | O35: 5420 | P35: 1 | Q35: 1 | R35: 006 | S35: 2 | T35: 0 | U35: 15 | V35: M190 | W35: 1183000 | X35: 1183000 | Y35: 7059 | Z35: CESSEL 001005 X | AB35: M190 | AC35: M190 | AD35: EB | AE35: LDS | AF35: SHS | AH35: EVERBEST LADIES SHOES ALMOND 36 | AI35: 15967 | AJ35: WLK999 | AL35: ART | AO35: JZ | AS35: 996902079772 | AT35: 001 | AU35: 005 | AY35: ADD 15%
A36: 28989 | B36: 1 | C36: 1690000 | D36: Special Offer | E36: 1005550 | F36: 46274 | G36: NAHLA | H36: M310 | I36: 0 | J36: 159865 | K36: 159865 | L36: 177450 | M36: 177450 | N36: FFO | O36: 28989 | P36: 1 | Q36: 1 | R36: 006 | S36: 2 | T36: 0 | U36: 15 | V36: M310 | W36: 1183000 | X36: 1183000 | Y36: 7059 | Z36: NAHLA 003007 X | AB36: M310 | AC36: M310 | AD36: EB | AE36: LDS | AF36: SHS | AH36: EVERBEST LADIES SHOES BLACK 40 | AI36: 16281 | AJ36: WLK999 | AL36: ART | AO36: KH | AS36: 996902081341 | AT36: 003 | AU36: 007 | AY36: ADD 15%
A37: 28989 | B37: 1 | C37: 1690000 | D37: Special Offer | E37: 1005550 | F37: 46274 | G37: NAHLA | H37: M310 | I37: 0 | J37: 159865 | K37: 159865 | L37: 177450 | M37: 177450 | N37: FFO | O37: 28989 | P37: 2 | Q37: 2 | R37: 006 | S37: 2 | T37: 0 | U37: 15 | V37: M310 | W37: 1183000 | X37: 1183000 | Y37: 7059 | Z37: NAHLA 00Z007 X | AB37: M310 | AC37: M310 | AD37: EB | AE37: LDS | AF37: SHS | AH37: EVERBEST LADIES SHOES TAN 40 | AI37: 16281 | AJ37: WLK999 | AL37: ART | AO37: KH | AS37: 996902081355 | AT37: 00Z | AU37: 007 | AY37: ADD 15%
A38: 28995 | B38: -1 | C38: 2990000 | D38: Special Offer | E38: -1270750 | F38: 46274 | G38: OLETHA | H38: M310 | I38: 0 | J38: -202027 | K38: -202027 | L38: -224250 | M38: -224250 | N38: FFO | O38: 28995 | P38: 2 | Q38: 20 | R38: 006 | S38: 2 | T38: 0 | U38: 15 | V38: M310 | W38: -1495000 | X38: -1495000 | Y38: 7059 | Z38: OLETHA 002001 X | AB38: M310 | AC38: M310 | AD38: EB | AE38: LDS | AF38: BAG | AH38: EVERBEST LADIES HANDBAGS BEIGE FREE SIZE | AI38: 17286 | AJ38: WLK999 | AL38: ART | AO38: HJX | AQ38: 25(L) x 105(H) x 25(W) cm | AS38: 996902072727 | AT38: 002 | AU38: 001 | AY38: ADD 15%
A39: 5419 | B39: 1 | C39: 2290000 | D39: Special Offer | E39: 1442700 | F39: 46274 | G39: GECCA | H39: M190 | I39: 0 | J39: 144414 | K39: 144414 | L39: 160300 | M39: 160300 | N39: FFO | O39: 5419 | P39: 2 | Q39: 2 | R39: 006 | S39: 2 | T39: 0 | U39: 10 | V39: M190 | W39: 1603000 | X39: 1603000 | Y39: 7059 | Z39: GECCA 001001 X | AB39: M190 | AC39: M190 | AD39: EB | AE39: LDS | AF39: BAG | AH39: EVERBEST LADIES BAGS ALMOND FREE SIZE | AI39: 15967 | AJ39: WLK999 | AL39: ART | AO39: EVG | AS39: 996902081881 | AT39: 001 | AU39: 001 | AY39: ADD 10%
A40: 28988 | B40: 1 | C40: 1990000 | D40: Special Offer | E40: 1184050 | F40: 46274 | G40: GERENA | H40: M310 | I40: 0 | J40: 188243 | K40: 188243 | L40: 208950 | M40: 208950 | N40: FFO | O40: 28988 | P40: 3 | Q40: 22 | R40: 006 | S40: 2 | T40: 0 | U40: 15 | V40: M310 | W40: 1393000 | X40: 1393000 | Y40: 7059 | Z40: GERENA 003001 X | AB40: M310 | AC40: M310 | AD40: EB | AE40: LDS | AF40: BAG | AH40: EVERBEST LADIES BAGS BLACK FREE SIZE | AI40: 17286 | AJ40: WLK999 | AL40: ART | AO40: HBYY | AS40: 996902082098 | AT40: 003 | AU40: 001 | AY40: ADD 15%
...

Sheet SUMMARY
A1: PROMO RESULT
A2: Kolom diskon: Qty = SUM(Quantity), Amount = SUM(Selling Price) per Store x Promo Type (sheet RAW). Total & LW Sales: penjualan brand per toko selama periode promo & periode LW (query sales toko).
A3: Jenis Promo: BUY2 ADD10%,BUY3 OR MORE ADD15% ON ALL D30-D50
A4: Store Code | B4: ADD 10% | D4: ADD 15% | F4: Total (2-30 Sep'26) | H4: Stock 1 Sep 2026 | I4: Sellthru | J4: Cont% | K4: LW Sales (29 Jul - 26 Agu'26) | M4: Growth%
B5: Qty | C5: Amount | D5: Qty | E5: Amount | F5: Qty | G5: Amount | K5: Qty | L5: Amount
A6: M010 | B6: =SUMIFS(RAW!$B$2:$B$64,RAW!$H$2:$H$64,$A6,RAW!$AY$2:$AY$64,B$4) | C6: =SUMIFS(RAW!$E$2:$E$64,RAW!$H$2:$H$64,$A6,RAW!$AY$2:$AY$64,B$4) | D6: =SUMIFS(RAW!$B$2:$B$64,RAW!$H$2:$H$64,$A6,RAW!$AY$2:$AY$64,D$4) | E6: =SUMIFS(RAW!$E$2:$E$64,RAW!$H$2:$H$64,$A6,RAW!$AY$2:$AY$64,D$4) | F6: 73 | G6: 102013850 | I6: =F6/H6 | J6: =F6/$F$11 | K6: 66 | L6: 91823000 | M6: =G6/L6-1
A7: M190 | B7: =SUMIFS(RAW!$B$2:$B$64,RAW!$H$2:$H$64,$A7,RAW!$AY$2:$AY$64,B$4) | C7: =SUMIFS(RAW!$E$2:$E$64,RAW!$H$2:$H$64,$A7,RAW!$AY$2:$AY$64,B$4) | D7: =SUMIFS(RAW!$B$2:$B$64,RAW!$H$2:$H$64,$A7,RAW!$AY$2:$AY$64,D$4) | E7: =SUMIFS(RAW!$E$2:$E$64,RAW!$H$2:$H$64,$A7,RAW!$AY$2:$AY$64,D$4) | F7: 41 | G7: 41296800 | I7: =F7/H7 | J7: =F7/$F$11 | K7: 42 | L7: 44551300 | M7: =G7/L7-1
A8: M310 | B8: =SUMIFS(RAW!$B$2:$B$64,RAW!$H$2:$H$64,$A8,RAW!$AY$2:$AY$64,B$4) | C8: =SUMIFS(RAW!$E$2:$E$64,RAW!$H$2:$H$64,$A8,RAW!$AY$2:$AY$64,B$4) | D8: =SUMIFS(RAW!$B$2:$B$64,RAW!$H$2:$H$64,$A8,RAW!$AY$2:$AY$64,D$4) | E8: =SUMIFS(RAW!$E$2:$E$64,RAW!$H$2:$H$64,$A8,RAW!$AY$2:$AY$64,D$4) | F8: 128 | G8: 156982850 | I8: =F8/H8 | J8: =F8/$F$11 | K8: 152 | L8: 213210150 | M8: =G8/L8-1
A9: M420 | B9: =SUMIFS(RAW!$B$2:$B$64,RAW!$H$2:$H$64,$A9,RAW!$AY$2:$AY$64,B$4) | C9: =SUMIFS(RAW!$E$2:$E$64,RAW!$H$2:$H$64,$A9,RAW!$AY$2:$AY$64,B$4) | D9: =SUMIFS(RAW!$B$2:$B$64,RAW!$H$2:$H$64,$A9,RAW!$AY$2:$AY$64,D$4) | E9: =SUMIFS(RAW!$E$2:$E$64,RAW!$H$2:$H$64,$A9,RAW!$AY$2:$AY$64,D$4) | F9: 17 | G9: 19532400 | I9: =F9/H9 | J9: =F9/$F$11 | K9: 62 | L9: 66235000 | M9: =G9/L9-1
A10: M730 | B10: =SUMIFS(RAW!$B$2:$B$64,RAW!$H$2:$H$64,$A10,RAW!$AY$2:$AY$64,B$4) | C10: =SUMIFS(RAW!$E$2:$E$64,RAW!$H$2:$H$64,$A10,RAW!$AY$2:$AY$64,B$4) | D10: =SUMIFS(RAW!$B$2:$B$64,RAW!$H$2:$H$64,$A10,RAW!$AY$2:$AY$64,D$4) | E10: =SUMIFS(RAW!$E$2:$E$64,RAW!$H$2:$H$64,$A10,RAW!$AY$2:$AY$64,D$4) | F10: 128 | G10: 221640150 | I10: =F10/H10 | J10: =F10/$F$11 | K10: 139 | L10: 244998700 | M10: =G10/L10-1
A11: GRAND TOTAL | B11: =SUM(B6:B10) | C11: =SUM(C6:C10) | D11: =SUM(D6:D10) | E11: =SUM(E6:E10) | F11: =SUM(F6:F10) | G11: =SUM(G6:G10) | H11: =SUM(H6:H10) | I11: =F11/H11 | J11: =1 | K11: =SUM(K6:K10) | L11: =SUM(L6:L10) | M11: =G11/L11-1
