Workbook

Sheet CONFIRMED PO
A1: PURCHASE ORDER | X1: PT. LARA THALIA ABADI
A2: PO NO | B2: : 5693 | L2: EVB | X2: EVERBEST TOWER - CENGKARENG BUSINESS CITY TOWER M
L3: NEW ARRIVAL | X3: Jl. Atang Sanjaya no. 21 Benda - Tangerang Banten, Indonesia
A4: DATE | B4: : 05 Jun 2026 | L4: FALL 2026 | X4: PHONE : 021 - 2252 9090
A5: TO | B5: : EDE | L5: MAKASSAR | X5: E-MAIL ADDRESS : buyer@everbestgroup.com
A8: DESCRIPTION | B8: DEVELOP CODE | C8: STYLE NAME | D8: COLOUR | F8: SETS | Y8: QTY CARTON PER 12 | Z8: QTY CARTON PER 8 | AA8: QTY PAIRS | AB8: UNIT PRICE | AC8: AMOUNT
F9: 12A | G9: 12B | H9: 12C | I9: 12D | J9: 12E | K9: 12F | L9: 12G | M9: 8H | N9: 8I | O9: 8J | P9: 8K | Q9: 8L | R9: 6M | S9: 6N | T9: 6O | U9: 6P | V9: 6Q | W9: 4R | X9: 4S
B10: 开发代码 | C10: 款式名称 | AB10: US$ | AC10: US$
A11: EVB LADIES SHOES - PUMP | B11: 262VB071 | C11: VEYLIN | D11: BLACK | F11: ='PACKING LIST'!K5 -> 0 | G11: ='PACKING LIST'!K8 -> 0 | H11: ='PACKING LIST'!K11 -> 0 | I11: ='PACKING LIST'!K14 -> 0 | J11: ='PACKING LIST'!K17 -> 0 | K11: ='PACKING LIST'!K20 -> 0 | L11: ='PACKING LIST'!K23 -> 0 | M11: ='PACKING LIST'!K26 -> 0 | N11: ='PACKING LIST'!K29 -> 0 | O11: ='PACKING LIST'!K32 -> 0 | P11: ='PACKING LIST'!K35 -> 0 | Q11: ='PACKING LIST'!K48 -> 0 | R11: ='PACKING LIST'!K41 -> 0 | S11: ='PACKING LIST'!K44 -> 0 | T11: ='PACKING LIST'!K47 -> 0 | U11: ='PACKING LIST'!K50 -> 0 | V11: ='PACKING LIST'!K53 -> 0 | W11: ='PACKING LIST'!K56 -> 0 | X11: ='PACKING LIST'!K59 -> 0 | Y11: =SUM(F11:L11)+SUM(R11:V11)/2 -> 0 | Z11: =SUM(M11:Q11)+SUM(W11:X11)/2 -> 0 | AA11: =SUM(F11:L11)*12+SUM(M11:Q11)*8+SUM(R11:V11)*6+SUM(W11:X11)*4 -> 0 | AB11: 16.57 | AC11: =AB11*AA11 -> 0
D12: BEIGE | F12: ='PACKING LIST'!X5 -> 0 | G12: ='PACKING LIST'!X8 -> 0 | H12: ='PACKING LIST'!X11 -> 0 | I12: ='PACKING LIST'!X14 -> 0 | J12: ='PACKING LIST'!X17 -> 0 | K12: ='PACKING LIST'!X20 -> 0 | L12: ='PACKING LIST'!X23 -> 0 | M12: ='PACKING LIST'!X26 -> 0 | N12: ='PACKING LIST'!X29 -> 0 | O12: ='PACKING LIST'!X32 -> 0 | P12: ='PACKING LIST'!X35 -> 0 | Q12: ='PACKING LIST'!X38 -> 0 | R12: ='PACKING LIST'!X41 -> 0 | S12: ='PACKING LIST'!X44 -> 0 | T12: ='PACKING LIST'!X47 -> 0 | U12: ='PACKING LIST'!X50 -> 0 | V12: ='PACKING LIST'!X53 -> 0 | W12: ='PACKING LIST'!X56 -> 0 | X12: ='PACKING LIST'!X59 -> 0 | Y12: =SUM(F12:L12)+SUM(R12:V12)/2 -> 0 | Z12: =SUM(M12:Q12)+SUM(W12:X12)/2 -> 0 | AA12: =SUM(F12:L12)*12+SUM(M12:Q12)*8+SUM(R12:V12)*6+SUM(W12:X12)*4 -> 0 | AB12: 16.57 | AC12: =AB12*AA12 -> 0
A13: Upper : FABRIC+PU | F13: ='PACKING LIST'!K69 -> 0 | G13: ='PACKING LIST'!K72 -> 0 | H13: ='PACKING LIST'!K75 -> 0 | I13: ='PACKING LIST'!K78 -> 0 | J13: ='PACKING LIST'!K81 -> 0 | K13: ='PACKING LIST'!K84 -> 0 | L13: ='PACKING LIST'!K87 -> 0 | M13: ='PACKING LIST'!K90 -> 0 | N13: ='PACKING LIST'!K93 -> 0 | O13: ='PACKING LIST'!K96 -> 0 | P13: ='PACKING LIST'!K99 -> 0 | Q13: ='PACKING LIST'!K102 -> 0 | R13: ='PACKING LIST'!K105 -> 0 | S13: ='PACKING LIST'!K108 -> 0 | T13: ='PACKING LIST'!K111 -> 0 | U13: ='PACKING LIST'!K114 -> 0 | V13: ='PACKING LIST'!K117 -> 0 | W13: ='PACKING LIST'!K120 -> 0 | X13: ='PACKING LIST'!K123 -> 0 | Y13: =SUM(F13:L13)+SUM(S13:V13)/2 -> 0 | Z13: =SUM(M13:Q13)+SUM(W13:X13)/2 -> 0 | AA13: =SUM(F13:L13)*12+SUM(M13:Q13)*8+SUM(R13:V13)*6+SUM(W13:X13)*4 -> 0 | AB13: 0 | AC13: =AB13*AA13 -> 0
A14: Lining : PU | F14: ='PACKING LIST'!X69 -> 0 | G14: ='PACKING LIST'!X72 -> 0 | H14: ='PACKING LIST'!X75 -> 0 | I14: ='PACKING LIST'!X78 -> 0 | J14: ='PACKING LIST'!X81 -> 0 | K14: ='PACKING LIST'!X84 -> 0 | L14: ='PACKING LIST'!X87 -> 0 | M14: ='PACKING LIST'!X90 -> 0 | N14: ='PACKING LIST'!X93 -> 0 | O14: ='PACKING LIST'!X96 -> 0 | P14: ='PACKING LIST'!X99 -> 0 | Q14: ='PACKING LIST'!X102 -> 0 | R14: ='PACKING LIST'!X105 -> 0 | S14: ='PACKING LIST'!X108 -> 0 | T14: ='PACKING LIST'!X111 -> 0 | U14: ='PACKING LIST'!X114 -> 0 | V14: ='PACKING LIST'!X117 -> 0 | W14: ='PACKING LIST'!X120 -> 0 | X14: ='PACKING LIST'!X124 -> 0 | Y14: =SUM(F14:L14)+SUM(S14:V14)/2 -> 0 | Z14: =SUM(M14:Q14)+SUM(W14:X14)/2 -> 0 | AA14: =SUM(F14:L14)*12+SUM(M14:Q14)*8+SUM(R14:V14)*6+SUM(W14:X14)*4 -> 0 | AB14: 0 | AC14: =AB14*AA14 -> 0
A15: Insole : PU
A16: Outsole : RUBBER
A17: Heel Height : 3-5 CM
Y18: =SUM(Y11:Y17) -> 0 | Z18: =SUM(Z11:Z17) -> 0 | AA18: =SUM(AA11:AA17) -> 0 | AC18: =SUM(AC11:AC17) -> 0
A19: Delivery Date | B19: 46209
A20: 交货日期
A21: LOGO : | P21: STYLE NAME | S21: COLOR | U21: SIZES | AB21: TOTAL QTY
A22: 商标 | U22: 35 | V22: =U22+1 -> 36 | W22: =V22+1 -> 37 | X22: =W22+1 -> 38 | Y22: =X22+1 -> 39 | Z22: =Y22+1 -> 40 | AA22: =Z22+1 -> 41
A23: TERM OF PAYMENT: | B23: CREDIT | P23: =C11 -> VEYLIN | S23: =D11 -> BLACK | U23: ='PACKING LIST'!B62 -> 0 | V23: 7 | W23: 13 | X23: 13 | Y23: 7 | Z23: 6 | AA23: ='PACKING LIST'!H62 -> 0 | AB23: =SUM(U23:AA23) -> 46
S24: =D12 -> BEIGE | U24: ='PACKING LIST'!O62 -> 0 | V24: 14 | W24: 20 | X24: 20 | Y24: 14 | Z24: 8 | AA24: ='PACKING LIST'!U62 -> 0 | AB24: =SUM(U24:AA24) -> 76
A25: CARTON MARK ： | S25: =D13 -> 0 | U25: ='PACKING LIST'!B126 -> 0 | V25: ='PACKING LIST'!C126 -> 0 | W25: ='PACKING LIST'!D126 -> 0 | X25: ='PACKING LIST'!E126 -> 0 | Y25: ='PACKING LIST'!F126 -> 0 | Z25: ='PACKING LIST'!G126 -> 0 | AA25: ='PACKING LIST'!H126 -> 0 | AB25: =SUM(U25:AA25) -> 0
A26: ( 箱标志 ) | S26: =D14 -> 0 | U26: ='PACKING LIST'!O126 -> 0 | V26: ='PACKING LIST'!P126 -> 0 | W26: ='PACKING LIST'!Q126 -> 0 | X26: ='PACKING LIST'!R126 -> 0 | Y26: ='PACKING LIST'!S126 -> 0 | Z26: ='PACKING LIST'!T126 -> 0 | AA26: ='PACKING LIST'!U126 -> 0 | AB26: =SUM(U26:AA26) -> 0
U27: =SUM(U23:U25) -> 0 | V27: =SUM(V23:V25) -> 21 | W27: =SUM(W23:W25) -> 33 | X27: =SUM(X23:X25) -> 33 | Y27: =SUM(Y23:Y25) -> 21 | Z27: =SUM(Z23:Z25) -> 14 | AA27: =SUM(AA23:AA25) -> 0 | AB27: =SUM(U27:AA27) -> 122
A30: PICTURE ( 图片 ):
A31: =B11 -> 262VB071
A32: =C11 -> VEYLIN
AD36: Please give us EXTRA TOPLIFT/DIAMOND INSIDE shoesbox, based on the shoes
AD37: 請給我們額外的TOPLIFT/DIAMOND 在鞋盒,根據鞋子
A43: =D11 -> BLACK | E43: =D12 -> BEIGE | N43: =D13 -> 0 | W43: =D14 -> 0
A45: SHOE BOX BARCODE : | F45: PACKAGING 包装: | M45: LINING | S45: SHOE MATERIAL CODE | Y45: QR CODE 二维码:
A46: (请贴这些条码在鞋盒按照图片) | F46: 鞋盒 和 箱子 包法 | M46: (打印在内里上） | S46: 鞋子材料贴标
M54: INSOLE 垫脚

Sheet PACKING LIST
A1: PACKING LIST PO
A3: ='CONFIRMED PO'!C11 -> VEYLIN | N3: =A3 -> VEYLIN
A4: ='CONFIRMED PO'!D11 -> BLACK | B4: 35 | C4: =B4+1 -> 36 | D4: =C4+1 -> 37 | E4: =D4+1 -> 38 | F4: =E4+1 -> 39 | G4: =F4+1 -> 40 | H4: =G4+1 -> 41 | K4: colly | L4: pairs | N4: ='CONFIRMED PO'!D12 -> BEIGE | O4: 35 | P4: =O4+1 -> 36 | Q4: =P4+1 -> 37 | R4: =Q4+1 -> 38 | S4: =R4+1 -> 39 | T4: =S4+1 -> 40 | U4: =T4+1 -> 41 | X4: colly | Y4: pairs
A5: SET A | B5: 1 | C5: 2 | D5: 3 | E5: 3 | F5: 2 | G5: 1 | I5: =SUM(B5:H5) -> 12 | J5: X | L5: =I5*K5 -> 0 | M5: A | N5: SET A | O5: 1 | P5: 2 | Q5: 3 | R5: 3 | S5: 2 | T5: 1 | V5: =SUM(O5:U5) -> 12 | W5: X | Y5: =V5*X5 -> 0 | Z5: A
A6: total A | B6: =B5*$K5 -> 0 | C6: =C5*$K5 -> 0 | D6: =D5*$K5 -> 0 | E6: =E5*$K5 -> 0 | F6: =F5*$K5 -> 0 | G6: =G5*$K5 -> 0 | H6: =H5*$K5 -> 0 | I6: =SUM(B6:H6) -> 0 | N6: total A | O6: =O5*$X5 -> 0 | P6: =P5*$X5 -> 0 | Q6: =Q5*$X5 -> 0 | R6: =R5*$X5 -> 0 | S6: =S5*$X5 -> 0 | T6: =T5*$X5 -> 0 | U6: =U5*$X5 -> 0 | V6: =SUM(O6:U6) -> 0
A8: SET B | C8: 1 | D8: 2 | E8: 3 | F8: 3 | G8: 2 | H8: 1 | I8: =SUM(B8:H8) -> 12 | J8: X | L8: =I8*K8 -> 0 | M8: B | N8: SET B | P8: 1 | Q8: 2 | R8: 3 | S8: 3 | T8: 2 | U8: 1 | V8: =SUM(O8:U8) -> 12 | W8: X | Y8: =V8*X8 -> 0 | Z8: B
A9: total B | B9: =B8*$K8 -> 0 | C9: =C8*$K8 -> 0 | D9: =D8*$K8 -> 0 | E9: =E8*$K8 -> 0 | F9: =F8*$K8 -> 0 | G9: =G8*$K8 -> 0 | H9: =H8*$K8 -> 0 | I9: =SUM(B9:H9) -> 0 | N9: total B | O9: =O8*$X8 -> 0 | P9: =P8*$X8 -> 0 | Q9: =Q8*$X8 -> 0 | R9: =R8*$X8 -> 0 | S9: =S8*$X8 -> 0 | T9: =T8*$X8 -> 0 | U9: =U8*$X8 -> 0 | V9: =SUM(O9:U9) -> 0
A11: SET C | B11: 1 | C11: 2 | D11: 2 | E11: 3 | F11: 2 | G11: 2 | I11: =SUM(B11:H11) -> 12 | J11: X | L11: =I11*K11 -> 0 | M11: C | N11: SET C | O11: 1 | P11: 2 | Q11: 2 | R11: 3 | S11: 2 | T11: 2 | V11: =SUM(O11:U11) -> 12 | W11: X | Y11: =V11*X11 -> 0 | Z11: C
A12: total C | B12: =B11*$K11 -> 0 | C12: =C11*$K11 -> 0 | D12: =D11*$K11 -> 0 | E12: =E11*$K11 -> 0 | F12: =F11*$K11 -> 0 | G12: =G11*$K11 -> 0 | H12: =H11*$K11 -> 0 | I12: =SUM(B12:H12) -> 0 | N12: total C | O12: =O11*$X11 -> 0 | P12: =P11*$X11 -> 0 | Q12: =Q11*$X11 -> 0 | R12: =R11*$X11 -> 0 | S12: =S11*$X11 -> 0 | T12: =T11*$X11 -> 0 | U12: =U11*$X11 -> 0 | V12: =SUM(O12:U12) -> 0
A14: SET D | B14: 2 | C14: 2 | D14: 3 | E14: 2 | F14: 2 | G14: 1 | I14: =SUM(B14:H14) -> 12 | J14: X | L14: =I14*K14 -> 0 | M14: D | N14: SET D | O14: 2 | P14: 2 | Q14: 3 | R14: 2 | S14: 2 | T14: 1 | V14: =SUM(O14:U14) -> 12 | W14: X | Y14: =V14*X14 -> 0 | Z14: D
A15: total D | B15: =B14*$K14 -> 0 | C15: =C14*$K14 -> 0 | D15: =D14*$K14 -> 0 | E15: =E14*$K14 -> 0 | F15: =F14*$K14 -> 0 | G15: =G14*$K14 -> 0 | H15: =H14*$K14 -> 0 | I15: =SUM(B15:H15) -> 0 | N15: total D | O15: =O14*$X14 -> 0 | P15: =P14*$X14 -> 0 | Q15: =Q14*$X14 -> 0 | R15: =R14*$X14 -> 0 | S15: =S14*$X14 -> 0 | T15: =T14*$X14 -> 0 | U15: =U14*$X14 -> 0 | V15: =SUM(O15:U15) -> 0
A17: SET E | B17: 1 | C17: 2 | D17: 2 | E17: 2 | F17: 2 | G17: 2 | H17: 1 | I17: =SUM(B17:H17) -> 12 | J17: X | L17: =I17*K17 -> 0 | M17: E | N17: SET E | O17: 1 | P17: 2 | Q17: 2 | R17: 2 | S17: 2 | T17: 2 | U17: 1 | V17: =SUM(O17:U17) -> 12 | W17: X | Y17: =V17*X17 -> 0 | Z17: E
A18: total E | B18: =B17*$K17 -> 0 | C18: =C17*$K17 -> 0 | D18: =D17*$K17 -> 0 | E18: =E17*$K17 -> 0 | F18: =F17*$K17 -> 0 | G18: =G17*$K17 -> 0 | H18: =H17*$K17 -> 0 | I18: =SUM(B18:H18) -> 0 | N18: total E | O18: =O17*$X17 -> 0 | P18: =P17*$X17 -> 0 | Q18: =Q17*$X17 -> 0 | R18: =R17*$X17 -> 0 | S18: =S17*$X17 -> 0 | T18: =T17*$X17 -> 0 | U18: =U17*$X17 -> 0 | V18: =SUM(O18:U18) -> 0
A20: SET F | B20: 1 | C20: 2 | D20: 3 | E20: 2 | F20: 2 | G20: 1 | H20: 1 | I20: =SUM(B20:H20) -> 12 | J20: X | L20: =I20*K20 -> 0 | M20: F | N20: SET F | O20: 1 | P20: 2 | Q20: 3 | R20: 2 | S20: 2 | T20: 1 | U20: 1 | V20: =SUM(O20:U20) -> 12 | W20: X | Y20: =V20*X20 -> 0 | Z20: F
A21: total F | B21: =B20*$K20 -> 0 | C21: =C20*$K20 -> 0 | D21: =D20*$K20 -> 0 | E21: =E20*$K20 -> 0 | F21: =F20*$K20 -> 0 | G21: =G20*$K20 -> 0 | H21: =H20*$K20 -> 0 | I21: =SUM(B21:H21) -> 0 | N21: total F | O21: =O20*$X20 -> 0 | P21: =P20*$X20 -> 0 | Q21: =Q20*$X20 -> 0 | R21: =R20*$X20 -> 0 | S21: =S20*$X20 -> 0 | T21: =T20*$X20 -> 0 | U21: =U20*$X20 -> 0 | V21: =SUM(O21:U21) -> 0
A23: SET G | C23: 2 | D23: 3 | E23: 3 | F23: 2 | G23: 2 | I23: =SUM(B23:H23) -> 12 | J23: X | L23: =I23*K23 -> 0 | M23: G | N23: SET G | P23: 2 | Q23: 3 | R23: 3 | S23: 2 | T23: 2 | V23: =SUM(O23:U23) -> 12 | W23: X | Y23: =V23*X23 -> 0 | Z23: G
A24: total G | B24: =B23*$K23 -> 0 | C24: =C23*$K23 -> 0 | D24: =D23*$K23 -> 0 | E24: =E23*$K23 -> 0 | F24: =F23*$K23 -> 0 | G24: =G23*$K23 -> 0 | H24: =H23*$K23 -> 0 | I24: =SUM(B24:H24) -> 0 | N24: total G | O24: =O23*$X23 -> 0 | P24: =P23*$X23 -> 0 | Q24: =Q23*$X23 -> 0 | R24: =R23*$X23 -> 0 | S24: =S23*$X23 -> 0 | T24: =T23*$X23 -> 0 | U24: =U23*$X23 -> 0 | V24: =SUM(O24:U24) -> 0
A26: SET H | B26: 1 | C26: 1 | D26: 2 | E26: 2 | F26: 1 | G26: 1 | I26: =SUM(B26:H26) -> 8 | J26: X | L26: =I26*K26 -> 0 | M26: H | N26: SET H | O26: 1 | P26: 1 | Q26: 2 | R26: 2 | S26: 1 | T26: 1 | V26: =SUM(O26:U26) -> 8 | W26: X | Y26: =V26*X26 -> 0 | Z26: H
A27: total H | B27: =B26*$K26 -> 0 | C27: =C26*$K26 -> 0 | D27: =D26*$K26 -> 0 | E27: =E26*$K26 -> 0 | F27: =F26*$K26 -> 0 | G27: =G26*$K26 -> 0 | H27: =H26*$K26 -> 0 | I27: =SUM(B27:H27) -> 0 | N27: total H | O27: =O26*$X26 -> 0 | P27: =P26*$X26 -> 0 | Q27: =Q26*$X26 -> 0 | R27: =R26*$X26 -> 0 | S27: =S26*$X26 -> 0 | T27: =T26*$X26 -> 0 | U27: =U26*$X26 -> 0 | V27: =SUM(O27:U27) -> 0
A29: SET I | C29: 1 | D29: 1 | E29: 2 | F29: 2 | G29: 1 | H29: 1 | I29: =SUM(B29:H29) -> 8 | J29: X | L29: =I29*K29 -> 0 | M29: I | N29: SET I | P29: 1 | Q29: 1 | R29: 2 | S29: 2 | T29: 1 | U29: 1 | V29: =SUM(O29:U29) -> 8 | W29: X | Y29: =V29*X29 -> 0 | Z29: I
A30: total I | B30: =B29*$K29 -> 0 | C30: =C29*$K29 -> 0 | D30: =D29*$K29 -> 0 | E30: =E29*$K29 -> 0 | F30: =F29*$K29 -> 0 | G30: =G29*$K29 -> 0 | H30: =H29*$K29 -> 0 | I30: =SUM(B30:H30) -> 0 | N30: total I | O30: =O29*$X29 -> 0 | P30: =P29*$X29 -> 0 | Q30: =Q29*$X29 -> 0 | R30: =R29*$X29 -> 0 | S30: =S29*$X29 -> 0 | T30: =T29*$X29 -> 0 | U30: =U29*$X29 -> 0 | V30: =SUM(O30:U30) -> 0
A32: SET J | C32: 1 | D32: 2 | E32: 2 | F32: 2 | G32: 1 | I32: =SUM(B32:H32) -> 8 | J32: X | L32: =I32*K32 -> 0 | M32: J | N32: SET J | P32: 1 | Q32: 2 | R32: 2 | S32: 2 | T32: 1 | V32: =SUM(O32:U32) -> 8 | W32: X | Y32: =V32*X32 -> 0 | Z32: J
A33: total J | B33: =B32*$K32 -> 0 | C33: =C32*$K32 -> 0 | D33: =D32*$K32 -> 0 | E33: =E32*$K32 -> 0 | F33: =F32*$K32 -> 0 | G33: =G32*$K32 -> 0 | H33: =H32*$K32 -> 0 | I33: =SUM(B33:H33) -> 0 | N33: total J | O33: =O32*$X32 -> 0 | P33: =P32*$X32 -> 0 | Q33: =Q32*$X32 -> 0 | R33: =R32*$X32 -> 0 | S33: =S32*$X32 -> 0 | T33: =T32*$X32 -> 0 | U33: =U32*$X32 -> 0 | V33: =SUM(O33:U33) -> 0
A35: SET K | C35: 2 | D35: 2 | E35: 2 | F35: 2 | I35: =SUM(B35:H35) -> 8 | J35: X | L35: =I35*K35 -> 0 | M35: K | N35: SET K | P35: 2 | Q35: 2 | R35: 2 | S35: 2 | V35: =SUM(O35:U35) -> 8 | W35: X | Y35: =V35*X35 -> 0 | Z35: K
A36: total K | B36: =B35*$K35 -> 0 | C36: =C35*$K35 -> 0 | D36: =D35*$K35 -> 0 | E36: =E35*$K35 -> 0 | F36: =F35*$K35 -> 0 | G36: =G35*$K35 -> 0 | H36: =H35*$K35 -> 0 | I36: =SUM(B36:H36) -> 0 | N36: total K | O36: =O35*$X35 -> 0 | P36: =P35*$X35 -> 0 | Q36: =Q35*$X35 -> 0 | R36: =R35*$X35 -> 0 | S36: =S35*$X35 -> 0 | T36: =T35*$X35 -> 0 | U36: =U35*$X35 -> 0 | V36: =SUM(O36:U36) -> 0
A38: SET L | D38: 2 | E38: 2 | F38: 2 | G38: 2 | I38: =SUM(B38:H38) -> 8 | J38: X | L38: =I38*K38 -> 0 | M38: L | N38: SET L | Q38: 2 | R38: 2 | S38: 2 | T38: 2 | V38: =SUM(O38:U38) -> 8 | W38: X | Y38: =V38*X38 -> 0 | Z38: L
A39: total L | B39: =B38*$K38 -> 0 | C39: =C38*$K38 -> 0 | D39: =D38*$K38 -> 0 | E39: =E38*$K38 -> 0 | F39: =F38*$K38 -> 0 | G39: =G38*$K38 -> 0 | H39: =H38*$K38 -> 0 | I39: =SUM(B39:H39) -> 0 | N39: total L | O39: =O38*$X38 -> 0 | P39: =P38*$X38 -> 0 | Q39: =Q38*$X38 -> 0 | R39: =R38*$X38 -> 0 | S39: =S38*$X38 -> 0 | T39: =T38*$X38 -> 0 | U39: =U38*$X38 -> 0 | V39: =SUM(O39:U39) -> 0
A41: SET M | B41: 1 | C41: 1 | D41: 1 | E41: 1 | F41: 1 | G41: 1 | I41: =SUM(B41:H41) -> 6 | J41: X | L41: =I41*K41 -> 0 | M41: M | N41: SET M | O41: 1 | P41: 1 | Q41: 1 | R41: 1 | S41: 1 | T41: 1 | V41: =SUM(O41:U41) -> 6 | W41: X | Y41: =V41*X41 -> 0 | Z41: M
A42: total M | B42: =B41*$K41 -> 0 | C42: =C41*$K41 -> 0 | D42: =D41*$K41 -> 0 | E42: =E41*$K41 -> 0 | F42: =F41*$K41 -> 0 | G42: =G41*$K41 -> 0 | H42: =H41*$K41 -> 0 | I42: =SUM(B42:H42) -> 0 | N42: total M | O42: =O41*$X41 -> 0 | P42: =P41*$X41 -> 0 | Q42: =Q41*$X41 -> 0 | R42: =R41*$X41 -> 0 | S42: =S41*$X41 -> 0 | T42: =T41*$X41 -> 0 | U42: =U41*$X41 -> 0 | V42: =SUM(O42:U42) -> 0
A44: SET N | C44: 1 | D44: 1 | E44: 1 | F44: 1 | G44: 1 | H44: 1 | I44: =SUM(B44:H44) -> 6 | J44: X | L44: =I44*K44 -> 0 | M44: N | N44: SET N | P44: 1 | Q44: 1 | R44: 1 | S44: 1 | T44: 1 | U44: 1 | V44: =SUM(O44:U44) -> 6 | W44: X | Y44: =V44*X44 -> 0 | Z44: N
A45: total N | B45: =B44*$K44 -> 0 | C45: =C44*$K44 -> 0 | D45: =D44*$K44 -> 0 | E45: =E44*$K44 -> 0 | F45: =F44*$K44 -> 0 | G45: =G44*$K44 -> 0 | H45: =H44*$K44 -> 0 | I45: =SUM(B45:H45) -> 0 | N45: total N | O45: =O44*$X44 -> 0 | P45: =P44*$X44 -> 0 | Q45: =Q44*$X44 -> 0 | R45: =R44*$X44 -> 0 | S45: =S44*$X44 -> 0 | T45: =T44*$X44 -> 0 | U45: =U44*$X44 -> 0 | V45: =SUM(O45:U45) -> 0
A47: SET O | C47: 1 | D47: 1 | E47: 2 | F47: 1 | G47: 1 | I47: =SUM(B47:H47) -> 6 | J47: X | L47: =I47*K47 -> 0 | M47: O | N47: SET O | P47: 1 | Q47: 1 | R47: 2 | S47: 1 | T47: 1 | V47: =SUM(O47:U47) -> 6 | W47: X | Y47: =V47*X47 -> 0 | Z47: O
A48: total O | B48: =B47*$K47 -> 0 | C48: =C47*$K47 -> 0 | D48: =D47*$K47 -> 0 | E48: =E47*$K47 -> 0 | F48: =F47*$K47 -> 0 | G48: =G47*$K47 -> 0 | H48: =H47*$K47 -> 0 | I48: =SUM(B48:H48) -> 0 | N48: total O | O48: =O47*$X47 -> 0 | P48: =P47*$X47 -> 0 | Q48: =Q47*$X47 -> 0 | R48: =R47*$X47 -> 0 | S48: =S47*$X47 -> 0 | T48: =T47*$X47 -> 0 | U48: =U47*$X47 -> 0 | V48: =SUM(O48:U48) -> 0
A50: SET P | C50: 1 | D50: 2 | E50: 2 | F50: 1 | I50: =SUM(B50:H50) -> 6 | J50: X | L50: =I50*K50 -> 0 | M50: P | N50: SET P | P50: 1 | Q50: 2 | R50: 2 | S50: 1 | V50: =SUM(O50:U50) -> 6 | W50: X | Y50: =V50*X50 -> 0 | Z50: P
A51: total P | B51: =B50*$K50 -> 0 | C51: =C50*$K50 -> 0 | D51: =D50*$K50 -> 0 | E51: =E50*$K50 -> 0 | F51: =F50*$K50 -> 0 | G51: =G50*$K50 -> 0 | H51: =H50*$K50 -> 0 | I51: =SUM(B51:H51) -> 0 | N51: total P | O51: =O50*$X50 -> 0 | P51: =P50*$X50 -> 0 | Q51: =Q50*$X50 -> 0 | R51: =R50*$X50 -> 0 | S51: =S50*$X50 -> 0 | T51: =T50*$X50 -> 0 | U51: =U50*$X50 -> 0 | V51: =SUM(O51:U51) -> 0
A53: SET Q | D53: 1 | E53: 2 | F53: 2 | G53: 1 | I53: =SUM(B53:H53) -> 6 | J53: X | L53: =I53*K53 -> 0 | M53: Q | N53: SET Q | Q53: 1 | R53: 2 | S53: 2 | T53: 1 | V53: =SUM(O53:U53) -> 6 | W53: X | Y53: =V53*X53 -> 0 | Z53: Q
A54: total Q | B54: =B53*$K53 -> 0 | C54: =C53*$K53 -> 0 | D54: =D53*$K53 -> 0 | E54: =E53*$K53 -> 0 | F54: =F53*$K53 -> 0 | G54: =G53*$K53 -> 0 | H54: =H53*$K53 -> 0 | I54: =SUM(B54:H54) -> 0 | N54: total Q | O54: =O53*$X53 -> 0 | P54: =P53*$X53 -> 0 | Q54: =Q53*$X53 -> 0 | R54: =R53*$X53 -> 0 | S54: =S53*$X53 -> 0 | T54: =T53*$X53 -> 0 | U54: =U53*$X53 -> 0 | V54: =SUM(O54:U54) -> 0
A56: SET R | C56: 1 | D56: 1 | E56: 1 | F56: 1 | I56: =SUM(B56:H56) -> 4 | J56: X | L56: =I56*K56 -> 0 | M56: R | N56: SET R | P56: 1 | Q56: 1 | R56: 1 | S56: 1 | V56: =SUM(O56:U56) -> 4 | W56: X | Y56: =V56*X56 -> 0 | Z56: R
A57: total R | B57: =B56*$K56 -> 0 | C57: =C56*$K56 -> 0 | D57: =D56*$K56 -> 0 | E57: =E56*$K56 -> 0 | F57: =F56*$K56 -> 0 | G57: =G56*$K56 -> 0 | H57: =H56*$K56 -> 0 | I57: =SUM(B57:H57) -> 0 | N57: total R | O57: =O56*$X56 -> 0 | P57: =P56*$X56 -> 0 | Q57: =Q56*$X56 -> 0 | R57: =R56*$X56 -> 0 | S57: =S56*$X56 -> 0 | T57: =T56*$X56 -> 0 | U57: =U56*$X56 -> 0 | V57: =SUM(O57:U57) -> 0
A59: SET S | D59: 1 | E59: 1 | F59: 1 | G59: 1 | I59: =SUM(B59:H59) -> 4 | J59: X | L59: =I59*K59 -> 0 | M59: S | N59: SET S | Q59: 1 | R59: 1 | S59: 1 | T59: 1 | V59: =SUM(O59:U59) -> 4 | W59: X | Y59: =V59*X59 -> 0 | Z59: S
...
