Workbook

Sheet CONFIRMED PO
A1: PURCHASE ORDER | K1: PT. LARA THALIA ABADI
A2: PO NO | B2: : | K2: EVERBEST TOWER - CENGKARENG BUSINESS CITY TOWER M
E3: TRACCE | K3: Jl. Atang Sanjaya no. 21 Benda - Tangerang Banten, Indonesia
A4: DATE | B4: : | K4: PHONE : 021 - 2252 9090
A5: TO | B5: : EDE | K5: E-MAIL ADDRESS : arisma@everbestgroup.com
A8: DESCRIPTION | B8: SUPPLIER CODE | C8: LTA ARTICLE | D8: COLOUR | E8: 颜色 | F8: SIZE RANGE | G8: 12 SET | K8: 6 SET | O8: QTY PAIRS | P8: QTY CARTON | Q8: UNIT PRICE | R8: AMOUNT
G9: A | H9: B | I9: C | J9: D | K9: E | L9: F | M9: G | N9: H
B10: 厂编号 | C10: 我司鞋编号 | Q10: US$ | R10: US$
E11: MAKE SAMPLE | I11: =IF(SUMIF('packing list'!$M$5:$M$28,I$9,'packing list'!$K$5:$K$28)=0,"",SUMIF('packing list'!$M$5:$M$28,I$9,'packing list'!$K$5:$K$28)) | M11: =IF(SUMIF('packing list'!$M$5:$M$28,M$9,'packing list'!$K$5:$K$28)=0,"",SUMIF('packing list'!$M$5:$M$28,M$9,'packing list'!$K$5:$K$28)) | N11: =IF(SUMIF('packing list'!$M$5:$M$28,N$9,'packing list'!$K$5:$K$28)=0,"",SUMIF('packing list'!$M$5:$M$28,N$9,'packing list'!$K$5:$K$28)) | O11: =SUM(G11:J11)*12+SUM(K11:N11)*6 -> 0 | P11: =SUM(G11:N11) -> 0 | R11: =Q11*O11 -> 0
E12: MAKE SAMPLE | J12: =IF(SUMIF('packing list'!$M$5:$M$28,J$9,'packing list'!$X$5:$X$28)=0,"",SUMIF('packing list'!$M$5:$M$28,J$9,'packing list'!$X$5:$X$28)) | K12: =IF(SUMIF('packing list'!$M$5:$M$28,K$9,'packing list'!$X$5:$X$28)=0,"",SUMIF('packing list'!$M$5:$M$28,K$9,'packing list'!$X$5:$X$28)) | L12: =IF(SUMIF('packing list'!$M$5:$M$28,L$9,'packing list'!$X$5:$X$28)=0,"",SUMIF('packing list'!$M$5:$M$28,L$9,'packing list'!$X$5:$X$28)) | M12: =IF(SUMIF('packing list'!$M$5:$M$28,M$9,'packing list'!$X$5:$X$28)=0,"",SUMIF('packing list'!$M$5:$M$28,M$9,'packing list'!$X$5:$X$28)) | N12: =IF(SUMIF('packing list'!$M$5:$M$28,N$9,'packing list'!$X$5:$X$28)=0,"",SUMIF('packing list'!$M$5:$M$28,N$9,'packing list'!$X$5:$X$28)) | O12: =SUM(G12:J12)*12+SUM(K12:N12)*6 -> 0 | P12: =SUM(G12:N12) -> 0 | R12: =Q12*O12 -> 0
E13: MAKE SAMPLE | G13: =IF(SUMIF('packing list'!$M$36:$M$59,G$9,'packing list'!$K$36:$K$59)=0,"",SUMIF('packing list'!$M$36:$M$59,G$9,'packing list'!$K$36:$K$59)) | H13: =IF(SUMIF('packing list'!$M$36:$M$59,H$9,'packing list'!$K$36:$K$59)=0,"",SUMIF('packing list'!$M$36:$M$59,H$9,'packing list'!$K$36:$K$59)) | I13: =IF(SUMIF('packing list'!$M$36:$M$59,I$9,'packing list'!$K$36:$K$59)=0,"",SUMIF('packing list'!$M$36:$M$59,I$9,'packing list'!$K$36:$K$59)) | J13: =IF(SUMIF('packing list'!$M$36:$M$59,J$9,'packing list'!$K$36:$K$59)=0,"",SUMIF('packing list'!$M$36:$M$59,J$9,'packing list'!$K$36:$K$59)) | L13: =IF(SUMIF('packing list'!$M$36:$M$59,L$9,'packing list'!$K$36:$K$59)=0,"",SUMIF('packing list'!$M$36:$M$59,L$9,'packing list'!$K$36:$K$59)) | M13: =IF(SUMIF('packing list'!$M$36:$M$59,M$9,'packing list'!$K$36:$K$59)=0,"",SUMIF('packing list'!$M$36:$M$59,M$9,'packing list'!$K$36:$K$59)) | N13: =IF(SUMIF('packing list'!$M$36:$M$59,N$9,'packing list'!$K$36:$K$59)=0,"",SUMIF('packing list'!$M$36:$M$59,N$9,'packing list'!$K$36:$K$59)) | O13: =SUM(G13:J13)*12+SUM(K13:N13)*6 -> 0 | P13: =SUM(G13:N13) -> 0
O15: =SUM(O11:O14) -> 0 | P15: =SUM(P11:P14) -> 0 | R15: =SUM(R11:R14) -> 0
A16: Delivery Date
A17: 交货日期 | F17: ARTICLE NAME | I17: COLOR | K17: SIZES | R17: TOTAL QTY
A18: LOGO : | K18: ='packing list'!B4 -> 35 | L18: =K18+1 -> 36 | M18: =L18+1 -> 37 | N18: =M18+1 -> 38 | O18: =N18+1 -> 39 | P18: =O18+1 -> 40 | Q18: =P18+1 -> 41
A19: 商标 | F19: =C11 -> 0 | I19: =D11 -> 0 | Q19: ='packing list'!H29 -> 0 | R19: =SUM(K19:Q19) -> 0
A20: TERM OF PAYMENT: | B20: CREDIT | I20: =D12 -> 0 | Q20: ='packing list'!U29 -> 0 | R20: =SUM(K20:Q20) -> 0
I21: =D13 -> 0 | Q21: ='packing list'!U30 -> 0 | R21: =SUM(K21:Q21) -> 0
A22: CARTON MARK ： | K22: =SUM(K19:K21) -> 0 | L22: =SUM(L19:L21) -> 0 | M22: =SUM(M19:M21) -> 0 | N22: =SUM(N19:N21) -> 0 | O22: =SUM(O19:O21) -> 0 | P22: =SUM(P19:P21) -> 0 | Q22: =SUM(Q19:Q21) -> 0 | R22: =SUM(K22:Q22) -> 0
A23: ( 箱标志 )
A26: PICTURE ( 图片 ):
A27: =C11 -> 0
A36: =D11 -> 0 | C36: =D12 -> 0 | F36: =D13 -> 0
A38: SHOE BOX BARCODE : | C38: PACKAGING 包装: | G38: LINING | K38: SHOE MATERIAL CODE | P38: QR CODE 二维码:
A39: (请贴这些条码在鞋盒按照图片) | C39: 鞋盒 和 箱子 包法 | G39: (打印在内里上） | K39: 鞋子材料贴标

Sheet packing list
A1: PACKING LIST PO
A3: ='CONFIRMED PO'!C11 -> 0 | N3: ='CONFIRMED PO'!C11 -> 0
A4: ='CONFIRMED PO'!D11 -> 0 | B4: 35 | C4: =B4+1 -> 36 | D4: =C4+1 -> 37 | E4: =D4+1 -> 38 | F4: =E4+1 -> 39 | G4: =F4+1 -> 40 | H4: =G4+1 -> 41 | K4: colly | L4: pairs | N4: ='CONFIRMED PO'!D12 -> 0 | O4: =B4 -> 35 | P4: =O4+1 -> 36 | Q4: =P4+1 -> 37 | R4: =Q4+1 -> 38 | S4: =R4+1 -> 39 | T4: =S4+1 -> 40 | U4: =T4+1 -> 41 | X4: colly | Y4: pairs
A5: SET A | B5: 1 | C5: 2 | D5: 3 | E5: 3 | F5: 2 | G5: 1 | I5: =SUM(B5:H5) -> 12 | J5: X | K5: 2 | L5: =I5*K5 -> 24 | M5: A | N5: SET A | O5: 1 | P5: 2 | Q5: 3 | R5: 3 | S5: 2 | T5: 1 | V5: =SUM(O5:U5) -> 12 | W5: X | X5: 2 | Y5: =V5*X5 -> 24
A6: total A | B6: =IFERROR(B5*$K$5,0) -> 2 | C6: =IFERROR(C5*$K$5,0) -> 4 | D6: =IFERROR(D5*$K$5,0) -> 6 | E6: =IFERROR(E5*$K$5,0) -> 6 | F6: =IFERROR(F5*$K$5,0) -> 4 | G6: =IFERROR(G5*$K$5,0) -> 2 | H6: =IFERROR(H5*$K$5,0) -> 0 | I6: =SUM(B6:H6) -> 24 | N6: total A | O6: =O5*$X$5 -> 2 | P6: =P5*$X$5 -> 4 | Q6: =Q5*$X$5 -> 6 | R6: =R5*$X$5 -> 6 | S6: =S5*$X$5 -> 4 | T6: =T5*$X$5 -> 2 | U6: =U5*$X$5 -> 0 | V6: =SUM(O6:U6) -> 24
A8: SET B | B8: 1 | C8: 1 | D8: 3 | E8: 3 | F8: 2 | G8: 2 | I8: =SUM(B8:H8) -> 12 | J8: X | K8: 2 | L8: =I8*K8 -> 24 | M8: B | N8: SET B | O8: 1 | P8: 1 | Q8: 3 | R8: 3 | S8: 2 | T8: 2 | V8: =SUM(O8:U8) -> 12 | W8: X | X8: 2 | Y8: =V8*X8 -> 24
A9: total B | B9: =IFERROR(B8*$K$8,0) -> 2 | C9: =IFERROR(C8*$K$8,0) -> 2 | D9: =IFERROR(D8*$K$8,0) -> 6 | E9: =IFERROR(E8*$K$8,0) -> 6 | F9: =IFERROR(F8*$K$8,0) -> 4 | G9: =IFERROR(G8*$K$8,0) -> 4 | H9: =IFERROR(H8*$K$8,0) -> 0 | I9: =SUM(B9:H9) -> 24 | N9: total B | O9: =O8*$X$8 -> 2 | P9: =P8*$X$8 -> 2 | Q9: =Q8*$X$8 -> 6 | R9: =R8*$X$8 -> 6 | S9: =S8*$X$8 -> 4 | T9: =T8*$X$8 -> 4 | U9: =U8*$X$8 -> 0 | V9: =SUM(O9:U9) -> 24
A11: SET C | C11: 1 | D11: 1 | E11: 1 | F11: 2 | G11: 1 | I11: =SUM(B11:H11) -> 6 | J11: X | L11: =I11*K11 -> 0 | M11: C | N11: SET C | O11: 1 | P11: 2 | Q11: 3 | R11: 3 | S11: 2 | T11: 1 | V11: =SUM(O11:U11) -> 12 | W11: X | X11: 1 | Y11: =V11*X11 -> 12
A12: total C | B12: =B11*$K$11 -> 0 | C12: =C11*$K$11 -> 0 | D12: =D11*$K$11 -> 0 | E12: =E11*$K$11 -> 0 | F12: =F11*$K$11 -> 0 | G12: =G11*$K$11 -> 0 | H12: =H11*$K$11 -> 0 | I12: =SUM(B12:H12) -> 0 | N12: total C | O12: =O11*$X$11 -> 1 | P12: =P11*$X$11 -> 2 | Q12: =Q11*$X$11 -> 3 | R12: =R11*$X$11 -> 3 | S12: =S11*$X$11 -> 2 | T12: =T11*$X$11 -> 1 | U12: =U11*$X$11 -> 0 | V12: =SUM(O12:U12) -> 12
A14: SET D | B14: 1 | C14: 1 | D14: 3 | E14: 3 | F14: 3 | G14: 1 | I14: =SUM(B14:H14) -> 12 | J14: X | K14: 1 | L14: =I14*K14 -> 12 | M14: D | N14: SET D | V14: =SUM(O14:U14) -> 0 | W14: X | Y14: =V14*X14 -> 0
A15: total D | B15: =B14*$K$14 -> 1 | C15: =C14*$K$14 -> 1 | D15: =D14*$K$14 -> 3 | E15: =E14*$K$14 -> 3 | F15: =F14*$K$14 -> 3 | G15: =G14*$K$14 -> 1 | H15: =H14*$K$14 -> 0 | I15: =SUM(B15:H15) -> 12 | N15: total D | O15: =O14*$X$14 -> 0 | P15: =P14*$X$14 -> 0 | Q15: =Q14*$X$14 -> 0 | R15: =R14*$X$14 -> 0 | S15: =S14*$X$14 -> 0 | T15: =T14*$X$14 -> 0 | U15: =U14*$X$14 -> 0 | V15: =SUM(O15:U15) -> 0
A17: SET E | B17: 1 | C17: 1 | D17: 1 | E17: 1 | F17: 1 | G17: 1 | I17: =SUM(B17:H17) -> 6 | J17: X | K17: 1 | L17: =I17*K17 -> 6 | M17: E | N17: SET E | V17: =SUM(O17:U17) -> 0 | W17: X | Y17: =V17*X17 -> 0
A18: total E | B18: =B17*$K$17 -> 1 | C18: =C17*$K$17 -> 1 | D18: =D17*$K$17 -> 1 | E18: =E17*$K$17 -> 1 | F18: =F17*$K$17 -> 1 | G18: =G17*$K$17 -> 1 | H18: =H17*$K$17 -> 0 | I18: =SUM(B18:H18) -> 6 | N18: total E | O18: =O17*$X$17 -> 0 | P18: =P17*$X$17 -> 0 | Q18: =Q17*$X$17 -> 0 | R18: =R17*$X$17 -> 0 | S18: =S17*$X$17 -> 0 | T18: =T17*$X$17 -> 0 | U18: =U17*$X$17 -> 0 | V18: =SUM(O18:U18) -> 0
A20: SET F | C20: 1 | D20: 1 | E20: 1 | F20: 2 | G20: 1 | I20: =SUM(B20:H20) -> 6 | J20: X | K20: 2 | L20: =I20*K20 -> 12 | M20: F | N20: SET F | V20: =SUM(O20:U20) -> 0 | W20: X | Y20: =V20*X20 -> 0
A21: total F | C21: =C20*$K$20 -> 2 | D21: =D20*$K$20 -> 2 | E21: =E20*$K$20 -> 2 | F21: =F20*$K$20 -> 4 | G21: =G20*$K$20 -> 2 | H21: =H20*$K$20 -> 0 | I21: =SUM(B21:H21) -> 12 | N21: total F | P21: =P20*$X$20 -> 0 | Q21: =Q20*$X$20 -> 0 | R21: =R20*$X$20 -> 0 | S21: =S20*$X$20 -> 0 | T21: =T20*$X$20 -> 0 | U21: =U20*$X$20 -> 0 | V21: =SUM(O21:U21) -> 0
A23: SET G | I23: =SUM(B23:H23) -> 0 | J23: X | L23: =I23*K23 -> 0 | M23: G | N23: SET G | V23: =SUM(O23:U23) -> 0 | W23: X | Y23: =V23*X23 -> 0
A24: total G | B24: =B23*$K$23 -> 0 | C24: =C23*$K$23 -> 0 | D24: =D23*$K$23 -> 0 | E24: =E23*$K$23 -> 0 | F24: =F23*$K$23 -> 0 | G24: =G23*$K$23 -> 0 | H24: =H23*$K$23 -> 0 | I24: =SUM(B24:H24) -> 0 | N24: total G | O24: =O23*$X$23 -> 0 | P24: =P23*$X$23 -> 0 | Q24: =Q23*$X$23 -> 0 | R24: =R23*$X$23 -> 0 | S24: =S23*$X$23 -> 0 | T24: =T23*$X$23 -> 0 | U24: =U23*$X$23 -> 0 | V24: =SUM(O24:U24) -> 0
A26: SET H | I26: =SUM(B26:H26) -> 0 | J26: X | L26: =I26*K26 -> 0 | M26: H | N26: SET H | V26: =SUM(O26:U26) -> 0 | W26: X | Y26: =V26*X26 -> 0
A27: total H | B27: =B26*$K$26 -> 0 | C27: =C26*$K$26 -> 0 | D27: =D26*$K$26 -> 0 | E27: =E26*$K$26 -> 0 | F27: =F26*$K$26 -> 0 | G27: =G26*$K$26 -> 0 | H27: =H26*$K$26 -> 0 | I27: =SUM(B27:H27) -> 0 | N27: total H | O27: =#N/A -> 0 | P27: =#N/A -> 0 | Q27: =#N/A -> 0 | R27: =#N/A -> 0 | S27: =#N/A -> 0 | V27: =SUM(O27:U27) -> 0
A29: total PO qty | B29: =SUM(B24,B21,B18,B15,B12,B9,B6,B27) -> 6 | C29: =SUM(C24,C21,C18,C15,C12,C9,C6,C27) -> 10 | D29: =SUM(D24,D21,D18,D15,D12,D9,D6,D27) -> 18 | E29: =SUM(E24,E21,E18,E15,E12,E9,E6,E27) -> 18 | F29: =SUM(F24,F21,F18,F15,F12,F9,F6,F27) -> 16 | G29: =SUM(G24,G21,G18,G15,G12,G9,G6,G27) -> 10 | H29: =SUM(H24,H21,H18,H15,H12,H9,H6,H27) -> 0 | I29: =SUM(I24,I21,I18,I15,I12,I9,I6,I27) -> 78 | N29: total PO qty | O29: =SUM(O24,O21,O18,O15,O12,O9,O6,O27) -> 5 | P29: =SUM(P24,P21,P18,P15,P12,P9,P6,P27) -> 8 | Q29: =SUM(Q24,Q21,Q18,Q15,Q12,Q9,Q6,Q27) -> 15 | R29: =SUM(R24,R21,R18,R15,R12,R9,R6,R27) -> 15 | S29: =SUM(S24,S21,S18,S15,S12,S9,S6,S27) -> 10 | T29: =SUM(T24,T21,T18,T15,T12,T9,T6,T27) -> 7 | U29: =SUM(U24,U21,U18,U15,U12,U9,U6,U27) -> 0 | V29: =SUM(V24,V21,V18,V15,V12,V9,V6,V27) -> 60
K30: =SUM(K5:K28) -> 8 | L30: =SUM(L5:L28) -> 78 | X30: =SUM(X5:X28) -> 5 | Y30: =SUM(Y5:Y28) -> 60
B31: =B23+B17 -> 1 | C31: =C23+C17 -> 1 | D31: =D23+D17 -> 1 | E31: =E23+E17 -> 1 | F31: =F23+F17 -> 1 | G31: =G23+G17 -> 1
A34: ='CONFIRMED PO'!C11 -> 0
A35: ='CONFIRMED PO'!D13 -> 0 | B35: =B4 -> 35 | C35: =B35+1 -> 36 | D35: =C35+1 -> 37 | E35: =D35+1 -> 38 | F35: =E35+1 -> 39 | G35: =F35+1 -> 40 | H35: =G35+1 -> 41 | K35: colly | L35: pairs
A36: SET A | B36: 1 | C36: 1 | D36: 1 | E36: 1 | F36: 1 | G36: 1 | I36: =SUM(B36:G36) -> 6 | J36: X | L36: =I36*K36 -> 0 | M36: A
A37: total A | B37: =B36*$K$36 -> 0 | C37: =#N/A -> 0 | D37: =#N/A -> 0 | E37: =#N/A -> 0 | F37: =#N/A -> 0 | G37: =#N/A -> 0 | I37: =SUM(B37:G37) -> 0
A39: SET B | I39: =SUM(B39:G39) -> 0 | J39: X | L39: =I39*K39 -> 0 | M39: B
A40: total B | B40: =B39*$K$39 -> 0 | C40: =#N/A -> 0 | D40: =#N/A -> 0 | E40: =#N/A -> 0 | F40: =#N/A -> 0 | G40: =#N/A -> 0 | I40: =SUM(B40:G40) -> 0
A42: SET C | I42: =SUM(B42:G42) -> 0 | J42: X | L42: =I42*K42 -> 0 | M42: C
A43: total C | B43: =B42*$K$42 -> 0 | C43: =#N/A -> 0 | D43: =#N/A -> 0 | E43: =#N/A -> 0 | F43: =#N/A -> 0 | G43: =#N/A -> 0 | I43: =SUM(B43:G43) -> 0
A45: SET D | I45: =SUM(B45:G45) -> 0 | J45: X | L45: =I45*K45 -> 0 | M45: D
A46: total D | B46: =B45*$K$45 -> 0 | C46: =#N/A -> 0 | D46: =#N/A -> 0 | E46: =#N/A -> 0 | F46: =#N/A -> 0 | G46: =#N/A -> 0 | I46: =SUM(B46:G46) -> 0
A48: SET E | B48: 1 | C48: 1 | D48: 1 | E48: 1 | F48: 1 | G48: 1 | I48: =SUM(B48:H48) -> 6 | J48: X | K48: 5 | L48: =I48*K48 -> 30 | M48: E
A49: total E | B49: =B48*$K$48 -> 5 | C49: =C48*$K$48 -> 5 | D49: =D48*$K$48 -> 5 | E49: =E48*$K$48 -> 5 | F49: =F48*$K$48 -> 5 | G49: =G48*$K$48 -> 5 | H49: =H48*$K$48 -> 0 | I49: =SUM(B49:H49) -> 30
A51: SET F | I51: =SUM(B51:H51) -> 0 | J51: X | L51: =I51*K51 -> 0 | M51: F
A52: total F | C52: =C51*$K$51 -> 0 | D52: =D51*$K$51 -> 0 | E52: =E51*$K$51 -> 0 | F52: =F51*$K$51 -> 0 | G52: =G51*$K$51 -> 0 | H52: =H51*$K$51 -> 0 | I52: =SUM(B52:H52) -> 0
A54: SET G | I54: =SUM(B54:G54) -> 0 | J54: X | L54: =I54*K54 -> 0 | M54: G
A55: total G | B55: =B54*$K$54 -> 0 | C55: =#N/A -> 0 | D55: =#N/A -> 0 | E55: =#N/A -> 0 | F55: =#N/A -> 0 | G55: =#N/A -> 0 | I55: =SUM(B55:G55) -> 0
A57: SET H | I57: =SUM(B57:G57) -> 0 | J57: X | L57: =I57*K57 -> 0 | M57: H
A58: total H | B58: =#N/A -> 0 | C58: =#N/A -> 0 | D58: =#N/A -> 0 | E58: =#N/A -> 0 | F58: =#N/A -> 0 | I58: =SUM(B58:G58) -> 0
...

Sheet Sheet2
B1: Jabodetabek | N1: Sumatera | V1: Kalimantan | AA1: Lombok | AB1: Sulawesi
B2: EVB SMB (Bekasi) | D2: EVB KGM (Jkt) | F2: MP | I2: Ecomm | J2: EB Aeon (Tgr) | K2: EB GMB (Bekasi) | L2: EB Puri (Jkt) | M2: EB Sency (Jkt) | N2: EVB SKA (Pekanbaru) | Q2: EVB CPM (Medan) | T2: EB PSQ (Palembang) | U2: TR Icon (Palembang) | V2: EVB Bumi Raya (Pontianak) | Y2: EVB SAMARINDA | Z2: EB Balikpapan | AA2: TR Lombok | AB2: EVB Kendari | AE2: EVB Panakukang (Mks) | AH2: EVB Mari (Mks) | AK2: EVB Mantos (Manado) | AN2: EVB Trans (Mks)
A3: 35 | B3: 5 | C3: =B3/SUM($B$3:$B$8) -> 0.098039216 | D3: 3 | E3: =D3/SUM($D$3:$D$8) -> 0.090909091 | F3: 5 | G3: =F3/SUM($F$3:$F$8) -> 0.058139535 | H3: =G3*$G$9 -> 0.46511628 | I3: 1 | N3: 6 | O3: =N3/SUM(N$3:N$8) -> 0.075 | P3: =O3*O$9 -> 0.9 | Q3: 6 | R3: =Q3/SUM($Q$3:$Q$8) -> 0.13953488 | S3: =R3*$R$9 -> 1.6744186 | V3: 3 | W3: =V3/SUM(V$3:V$8) -> 0.066666667 | X3: =W3*W$9 -> 0.8 | Y3: 3 | AA3: 1 | AB3: 3 | AC3: =AB3/SUM($AB$3:$AB$8) -> 0.06 | AD3: =#N/A -> 0.72 | AE3: 10 | AF3: =AE3/SUM($AE$3:$AE$8) -> 0.11363636 | AG3: =AF3*$AF$9 -> 2.2727273 | AH3: 8 | AI3: =AH3/SUM($AH$3:$AH$8) -> 0.13333333 | AJ3: =AI3*$AI$9 -> 2.6666667 | AK3: 6 | AL3: =AK3/SUM($AK$3:$AK$8) -> 0.13043478 | AM3: =AL3*$AL$9 -> 2.6086957 | AN3: 6 | AO3: 41 | AP3: 0.10301508 | AQ3: =AP3*$AP$9 -> 1.6482412
A4: 36 | B4: 6 | C4: =B4/SUM($B$3:$B$8) -> 0.11764706 | D4: 3 | E4: =D4/SUM($D$3:$D$8) -> 0.090909091 | F4: 19 | G4: =F4/SUM($F$3:$F$8) -> 0.22093023 | H4: =G4*$G$9 -> 1.7674419 | I4: 1 | N4: 15 | O4: =N4/SUM(N$3:N$8) -> 0.1875 | P4: =O4*O$9 -> 2.25 | Q4: 6 | R4: =Q4/SUM($Q$3:$Q$8) -> 0.13953488 | S4: =R4*$R$9 -> 1.6744186 | V4: 9 | W4: =V4/SUM(V$3:V$8) -> 0.2 | X4: =W4*W$9 -> 2.4 | Y4: 6 | AA4: 3 | AB4: 10 | AC4: =AB4/SUM($AB$3:$AB$8) -> 0.2 | AD4: =#N/A -> 2.4 | AE4: 16 | AF4: =AE4/SUM($AE$3:$AE$8) -> 0.18181818 | AG4: =AF4*$AF$9 -> 3.6363636 | AH4: 10 | AI4: =AH4/SUM($AH$3:$AH$8) -> 0.16666667 | AJ4: =AI4*$AI$9 -> 3.3333333 | AK4: 9 | AL4: =AK4/SUM($AK$3:$AK$8) -> 0.19565217 | AM4: =AL4*$AL$9 -> 3.9130435 | AN4: 9 | AO4: 74 | AP4: 0.18592965 | AQ4: =AP4*$AP$9 -> 2.9748744
A5: 37 | B5: 10 | C5: =B5/SUM($B$3:$B$8) -> 0.19607843 | D5: 11 | E5: =D5/SUM($D$3:$D$8) -> 0.33333333 | F5: 24 | G5: =F5/SUM($F$3:$F$8) -> 0.27906977 | H5: =G5*$G$9 -> 2.2325581 | I5: 6 | N5: 26 | O5: =N5/SUM(N$3:N$8) -> 0.325 | P5: =O5*O$9 -> 3.9 | Q5: 10 | R5: =Q5/SUM($Q$3:$Q$8) -> 0.23255814 | S5: =R5*$R$9 -> 2.7906977 | V5: 15 | W5: =V5/SUM(V$3:V$8) -> 0.33333333 | X5: =W5*W$9 -> 4 | Y5: 11 | AA5: 8 | AB5: 15 | AC5: =AB5/SUM($AB$3:$AB$8) -> 0.3 | AD5: =#N/A -> 3.6 | AE5: 26 | AF5: =AE5/SUM($AE$3:$AE$8) -> 0.29545455 | AG5: =AF5*$AF$9 -> 5.9090909 | AH5: 15 | AI5: =AH5/SUM($AH$3:$AH$8) -> 0.25 | AJ5: =AI5*$AI$9 -> 5 | AK5: 14 | AL5: =AK5/SUM($AK$3:$AK$8) -> 0.30434783 | AM5: =AL5*$AL$9 -> 6.0869565 | AN5: 14 | AO5: 114 | AP5: 0.28643216 | AQ5: =AP5*$AP$9 -> 4.5829146
A6: 38 | B6: 14 | C6: =B6/SUM($B$3:$B$8) -> 0.2745098 | D6: 7 | E6: =D6/SUM($D$3:$D$8) -> 0.21212121 | F6: 20 | G6: =F6/SUM($F$3:$F$8) -> 0.23255814 | H6: =G6*$G$9 -> 1.8604651 | I6: 4 | N6: 16 | O6: =N6/SUM(N$3:N$8) -> 0.2 | P6: =O6*O$9 -> 2.4 | Q6: 11 | R6: =Q6/SUM($Q$3:$Q$8) -> 0.25581395 | S6: =R6*$R$9 -> 3.0697674 | U6: 1 | V6: 7 | W6: =V6/SUM(V$3:V$8) -> 0.15555556 | X6: =W6*W$9 -> 1.8666667 | Y6: 10 | AA6: 7 | AB6: 17 | AC6: =AB6/SUM($AB$3:$AB$8) -> 0.34 | AD6: =#N/A -> 4.08 | AE6: 18 | AF6: =AE6/SUM($AE$3:$AE$8) -> 0.20454545 | AG6: =AF6*$AF$9 -> 4.0909091 | AH6: 17 | AI6: =AH6/SUM($AH$3:$AH$8) -> 0.28333333 | AJ6: =AI6*$AI$9 -> 5.6666667 | AK6: 9 | AL6: =AK6/SUM($AK$3:$AK$8) -> 0.19565217 | AM6: =AL6*$AL$9 -> 3.9130435 | AN6: 9 | AO6: 96 | AP6: 0.24120603 | AQ6: =AP6*$AP$9 -> 3.8592965
A7: 39 | B7: 12 | C7: =B7/SUM($B$3:$B$8) -> 0.23529412 | D7: 7 | E7: =D7/SUM($D$3:$D$8) -> 0.21212121 | F7: 13 | G7: =F7/SUM($F$3:$F$8) -> 0.15116279 | H7: =G7*$G$9 -> 1.2093023 | I7: 1 | N7: 12 | O7: =N7/SUM(N$3:N$8) -> 0.15 | P7: =O7*O$9 -> 1.8 | Q7: 7 | R7: =Q7/SUM($Q$3:$Q$8) -> 0.1627907 | S7: =R7*$R$9 -> 1.9534884 | V7: 9 | W7: =V7/SUM(V$3:V$8) -> 0.2 | X7: =W7*W$9 -> 2.4 | Y7: 3 | AA7: 6 | AB7: 5 | AC7: =AB7/SUM($AB$3:$AB$8) -> 0.1 | AD7: =#N/A -> 1.2 | AE7: 12 | AF7: =AE7/SUM($AE$3:$AE$8) -> 0.13636364 | AG7: =AF7*$AF$9 -> 2.7272727 | AH7: 5 | AI7: =AH7/SUM($AH$3:$AH$8) -> 0.083333333 | AJ7: =AI7*$AI$9 -> 1.6666667 | AK7: 6 | AL7: =AK7/SUM($AK$3:$AK$8) -> 0.13043478 | AM7: =AL7*$AL$9 -> 2.6086957 | AN7: 6 | AO7: 55 | AP7: 0.13819095 | AQ7: =AP7*$AP$9 -> 2.2110553
A8: 40 | B8: 4 | C8: =B8/SUM($B$3:$B$8) -> 0.078431373 | D8: 2 | E8: =D8/SUM($D$3:$D$8) -> 0.060606061 | F8: 5 | G8: =F8/SUM($F$3:$F$8) -> 0.058139535 | H8: =G8*$G$9 -> 0.46511628 | I8: 2 | N8: 5 | O8: =N8/SUM(N$3:N$8) -> 0.0625 | P8: =O8*O$9 -> 0.75 | Q8: 3 | R8: =Q8/SUM($Q$3:$Q$8) -> 0.069767442 | S8: =R8*$R$9 -> 0.8372093 | V8: 2 | W8: =V8/SUM(V$3:V$8) -> 0.044444444 | X8: =W8*W$9 -> 0.53333333 | Y8: 1 | AA8: 2 | AE8: 6 | AF8: =AE8/SUM($AE$3:$AE$8) -> 0.068181818 | AG8: =AF8*$AF$9 -> 1.3636364 | AH8: 5 | AI8: =AH8/SUM($AH$3:$AH$8) -> 0.083333333 | AJ8: =AI8*$AI$9 -> 1.6666667 | AK8: 2 | AL8: =AK8/SUM($AK$3:$AK$8) -> 0.043478261 | AM8: =AL8*$AL$9 -> 0.86956522 | AN8: 2 | AO8: 18 | AP8: 0.045226131 | AQ8: =AP8*$AP$9 -> 0.72361809
G9: 8 | O9: 12 | R9: 12 | W9: 12 | AC9: 12 | AF9: 20 | AI9: 20 | AL9: 20 | AP9: 16
