Workbook

Sheet PO
A1: PURCHASE ORDER
A2: PO NO | B2: : | E2: TRACCE | N2: EVERBEST TOWER - CENGKARENG BUSINESS CITY TOWER M
N3: Jl. Atang Sanjaya no. 21 Benda - Tangerang Banten, Indonesia
A4: DATE | N4: PHONE : 021 - 2252 9090
A5: TO | B5: : EDE | N5: E-MAIL ADDRESS : buyer@everbestgroup.com
A6: FACTORY | B6: : LS
A8: DESCRIPTION | B8: SUPPLIER CODE | C8: LTA ARTICLE | D8: COLOUR | E8: 颜色 | F8: SIZE RANGE | R8: QTY PAIRS | S8: UNIT PRICE | T8: AMOUNT
F9: ='packing list'!B7 -> 26 | G9: =F9+1 -> 27 | H9: =G9+1 -> 28 | I9: =H9+1 -> 29 | J9: =I9+1 -> 30 | K9: =J9+1 -> 31 | L9: =K9+1 -> 32 | M9: =L9+1 -> 33 | N9: =M9+1 -> 34 | ... Q9: =P9+1 -> 37
B10: 厂编号 | C10: 我司鞋编号 | S10: US$ | T10: US$
E11: AS SAMPLE | Q11: =IFERROR(HLOOKUP(Q$9,'packing list'!$B$7:$H$36,30,0),"") | R11: =SUM(F11:Q11) -> 0 | T11: =S11*R11 -> 0
E12: AS SAMPLE | R12: =SUM(F12:Q12) -> 0 | T12: =S12*R12 -> 0
E13: AS SAMPLE | R13: =SUM(F13:Q13) -> 0 | T13: =S13*R13 -> 0
R16: =SUM(R11:R15) -> 0 | T16: =SUM(T11:T15) -> 0
A17: Delivery Date
A18: 交货日期
A19: LOGO :
A20: 商标
A21: TERM OF PAYMENT: | B21: CREDIT
A23: CARTON MARK ：
A24: ( 箱标志 )
A28: =C11 -> 0 | L28: NOTE
A37: =D11 -> 0 | B37: =D12 -> 0
A39: SHOE BOX BARCODE : | C39: PACKAGING 包装: | L39: LINING | Q39: SHOE MATERIAL CODE | T39: QR CODE 二维码:
A40: (请贴这些条码在鞋盒按照图片) | C40: 鞋盒 和 箱子 包法 | L40: (打印在内里上） | Q40: 鞋子材料贴标
L50: INSOLE 垫脚

Sheet packing list
A1: PACKING LIST PO
A6: =PO!C11 -> 0 | N6: =A6 -> 0
A7: =PO!D11 -> 0 | B7: 26 | C7: =B7+1 -> 27 | D7: =C7+1 -> 28 | E7: =D7+1 -> 29 | F7: =E7+1 -> 30 | G7: =F7+1 -> 31 | J7: colly | K7: pairs | N7: =A7 -> 0 | O7: =G7+1 -> 32 | P7: =O7+1 -> 33 | Q7: =P7+1 -> 34 | R7: =Q7+1 -> 35 | S7: =R7+1 -> 36 | T7: =S7+1 -> 37 | W7: colly | X7: pairs
A8: SET A | B8: 1 | C8: 1 | D8: 2 | E8: 1 | F8: 1 | G8: 2 | H8: =SUM(B8:G8) -> 8 | I8: X | J8: 2 | K8: =J8*H8 -> 16 | L8: A | N8: SET A | O8: 2 | P8: 2 | Q8: 2 | R8: 1 | S8: 1 | U8: =SUM(O8:T8) -> 8 | V8: X | W8: 1 | X8: =W8*U8 -> 8
A9: total A | B9: =B8*J8 -> 2 | C9: =C8*J8 -> 2 | D9: =D8*J8 -> 4 | E9: =E8*J8 -> 2 | F9: =F8*J8 -> 2 | G9: =G8*J8 -> 4 | H9: =SUM(B9:G9) -> 16 | N9: total A | O9: =O8*W8 -> 2 | P9: =P8*W8 -> 2 | Q9: =Q8*W8 -> 2 | R9: =R8*W8 -> 1 | S9: =S8*W8 -> 1 | U9: =SUM(O9:T9) -> 8
A11: SET B | B11: 1 | C11: 1 | D11: 1 | E11: 1 | F11: 1 | G11: 1 | H11: =SUM(B11:G11) -> 6 | I11: X | J11: 1 | K11: =J11*H11 -> 6 | L11: B | N11: SET B | O11: 2 | P11: 2 | Q11: 1 | R11: 1 | U11: =SUM(O11:T11) -> 6 | V11: X | W11: 1 | X11: =W11*U11 -> 6
A12: total B | B12: =B11*$J$11 -> 1 | C12: =C11*$J$11 -> 1 | D12: =D11*$J$11 -> 1 | E12: =E11*$J$11 -> 1 | F12: =F11*$J$11 -> 1 | G12: =G11*$J$11 -> 1 | H12: =SUM(B12:G12) -> 6 | N12: total B | O12: =O11*W11 -> 2 | P12: =P11*W11 -> 2 | Q12: =Q11*W11 -> 1 | R12: =R11*W11 -> 1 | S12: =S11*W11 -> 0 | U12: =SUM(O12:T12) -> 6
A14: SET C | B14: 2 | C14: 2 | D14: 2 | E14: 2 | F14: 2 | G14: 2 | H14: =SUM(B14:G14) -> 12 | I14: X | J14: 3 | K14: =J14*H14 -> 36 | L14: C | N14: SET C | O14: 1 | P14: 1 | Q14: 2 | R14: 1 | S14: 1 | U14: =SUM(O14:T14) -> 6 | V14: X | W14: 1 | X14: =W14*U14 -> 6
A15: total C | B15: =B14*J14 -> 6 | C15: =C14*J14 -> 6 | D15: =D14*J14 -> 6 | E15: =E14*J14 -> 6 | F15: =F14*J14 -> 6 | G15: =G14*J14 -> 6 | H15: =SUM(B15:G15) -> 36 | N15: total C | O15: =O14*W14 -> 1 | P15: =P14*W14 -> 1 | Q15: =Q14*W14 -> 2 | R15: =R14*W14 -> 1 | S15: =S14*W14 -> 1 | U15: =SUM(O15:T15) -> 6
A17: SET D | H17: =SUM(B17:G17) -> 0 | I17: X | K17: =J17*H17 -> 0 | N17: SET D | O17: 3 | P17: 3 | Q17: 3 | R17: 2 | S17: 1 | U17: =SUM(O17:T17) -> 12 | V17: X | W17: 3 | X17: =W17*U17 -> 36
A18: total D | B18: =B17*J17 -> 0 | C18: =C17*J17 -> 0 | D18: =D17*J17 -> 0 | E18: =E17*J17 -> 0 | F18: =F17*J17 -> 0 | G18: =G17*J17 -> 0 | H18: =SUM(B18:G18) -> 0 | N18: total D | O18: =O17*W17 -> 9 | P18: =P17*W17 -> 9 | Q18: =Q17*W17 -> 9 | R18: =R17*W17 -> 6 | S18: =S17*W17 -> 3 | U18: =SUM(O18:T18) -> 36
A20: SET E | H20: =SUM(B20:G20) -> 0 | I20: X | N20: SET E | U20: =SUM(O20:T20) -> 0 | V20: X | X20: =W20*U20 -> 0
A21: total E | H21: =SUM(B21:G21) -> 0 | N21: total E | O21: =O20*W20 -> 0 | P21: =P20*W20 -> 0 | Q21: =Q20*W20 -> 0 | R21: =R20*W20 -> 0 | S21: =S20*W20 -> 0 | U21: =SUM(O21:T21) -> 0
A23: SET F | H23: =SUM(B23:G23) -> 0 | I23: X | N23: SET F | U23: =SUM(O23:T23) -> 0 | V23: X
A24: total F | H24: =SUM(B24:G24) -> 0 | N24: total F | U24: =SUM(O24:T24) -> 0
A26: SET G | H26: =SUM(B26:G26) -> 0 | I26: X | N26: SET G | U26: =SUM(O26:T26) -> 0 | V26: X
A27: total G | H27: =SUM(B27:G27) -> 0 | N27: total G | U27: =SUM(O27:T27) -> 0
A29: SET H | H29: =SUM(B29:G29) -> 0 | I29: X | N29: SET H | U29: =SUM(O29:T29) -> 0 | V29: X
A30: total H | H30: =SUM(B30:G30) -> 0 | N30: total H | U30: =SUM(O30:T30) -> 0
A32: SET R | H32: =SUM(B32:G32) -> 0 | I32: X | N32: SET R | U32: =SUM(O32:T32) -> 0 | V32: X
A33: total R | H33: =SUM(B33:G33) -> 0 | N33: total R | U33: =SUM(O33:T33) -> 0
A36: total PO qty | B36: =SUM(B27,B24,B21,B18,B15,B12,B9,B30,B33) -> 9 | C36: =SUM(C27,C24,C21,C18,C15,C12,C9,C30,C33) -> 9 | D36: =SUM(D27,D24,D21,D18,D15,D12,D9,D30,D33) -> 11 | E36: =SUM(E27,E24,E21,E18,E15,E12,E9,E30,E33) -> 9 | F36: =SUM(F27,F24,F21,F18,F15,F12,F9,F30,F33) -> 9 | G36: =SUM(G27,G24,G21,G18,G15,G12,G9,G30,G33) -> 11 | H36: =SUM(B36:G36) -> 58 | J36: =SUM(J8:J19) -> 6 | K36: =SUM(K8:K19) -> 58 | N36: total PO qty | O36: =SUM(O27,O24,O21,O18,O15,O12,O9,O30,O33) -> 14 | P36: =SUM(P27,P24,P21,P18,P15,P12,P9,P30,P33) -> 14 | Q36: =SUM(Q27,Q24,Q21,Q18,Q15,Q12,Q9,Q30,Q33) -> 14 | R36: =SUM(R27,R24,R21,R18,R15,R12,R9,R30,R33) -> 9 | S36: =SUM(S27,S24,S21,S18,S15,S12,S9,S30,S33) -> 5 | T36: =SUM(T27,T24,T21,T18,T15,T12,T9,T30,T33) -> 0 | U36: =SUM(O36:T36) -> 56 | W36: =SUM(W8:W20) -> 6 | X36: =SUM(X8:X20) -> 56
A40: =A6 -> 0 | N40: =A40 -> 0
A41: =PO!D13 -> 0 | B41: 26 | C41: =B41+1 -> 27 | D41: =C41+1 -> 28 | E41: =D41+1 -> 29 | F41: =E41+1 -> 30 | G41: =F41+1 -> 31 | J41: colly | K41: pairs | N41: =A41 -> 0 | O41: =G41+1 -> 32 | P41: =O41+1 -> 33 | Q41: =P41+1 -> 34 | R41: =Q41+1 -> 35 | S41: =R41+1 -> 36 | T41: =S41+1 -> 37 | W41: colly | X41: pairs
A42: SET A | B42: 1 | C42: 1 | D42: 2 | E42: 1 | F42: 1 | G42: 2 | H42: =SUM(B42:G42) -> 8 | I42: X | J42: 2 | K42: =J42*H42 -> 16 | L42: A | N42: SET A | U42: =SUM(O42:T42) -> 0 | V42: X | X42: =W42*U42 -> 0
A43: total A | B43: =B42*J42 -> 2 | C43: =C42*J42 -> 2 | D43: =D42*J42 -> 4 | E43: =E42*J42 -> 2 | F43: =F42*J42 -> 2 | G43: =G42*J42 -> 4 | H43: =SUM(B43:G43) -> 16 | N43: total A | O43: =O42*W42 -> 0 | P43: =P42*W42 -> 0 | Q43: =Q42*W42 -> 0 | R43: =R42*W42 -> 0 | S43: =S42*W42 -> 0 | U43: =SUM(O43:T43) -> 0
A45: SET B | B45: 1 | C45: 1 | D45: 1 | E45: 1 | F45: 1 | G45: 1 | H45: =SUM(B45:G45) -> 6 | I45: X | J45: 1 | K45: =J45*H45 -> 6 | L45: B | N45: SET B | U45: =SUM(O45:T45) -> 0 | V45: X | X45: =W45*U45 -> 0
A46: total B | B46: =B45*$J$45 -> 1 | C46: =C45*$J$45 -> 1 | D46: =D45*$J$45 -> 1 | E46: =E45*$J$45 -> 1 | F46: =F45*$J$45 -> 1 | G46: =G45*$J$45 -> 1 | H46: =SUM(B46:G46) -> 6 | N46: total B | O46: =O45*W45 -> 0 | P46: =P45*W45 -> 0 | Q46: =Q45*W45 -> 0 | R46: =R45*W45 -> 0 | S46: =S45*W45 -> 0 | U46: =SUM(O46:T46) -> 0
A48: SET C | B48: 2 | C48: 2 | D48: 2 | E48: 2 | F48: 2 | G48: 2 | H48: =SUM(B48:G48) -> 12 | I48: X | J48: 3 | K48: =J48*H48 -> 36 | L48: C | N48: SET C | U48: =SUM(O48:T48) -> 0 | V48: X | X48: =W48*U48 -> 0
A49: total C | B49: =B48*$J$48 -> 6 | C49: =C48*$J$48 -> 6 | D49: =D48*$J$48 -> 6 | E49: =E48*$J$48 -> 6 | F49: =F48*$J$48 -> 6 | G49: =G48*$J$48 -> 6 | H49: =SUM(B49:G49) -> 36 | N49: total C | O49: =O48*W48 -> 0 | P49: =P48*W48 -> 0 | Q49: =Q48*W48 -> 0 | R49: =R48*W48 -> 0 | S49: =S48*W48 -> 0 | U49: =SUM(O49:T49) -> 0
A51: SET D | H51: =SUM(B51:G51) -> 0 | I51: X | K51: =J51*H51 -> 0 | N51: SET D | U51: =SUM(O51:T51) -> 0 | V51: X | X51: =W51*U51 -> 0
A52: total D | H52: =SUM(B52:G52) -> 0 | N52: total D | O52: =O51*W51 -> 0 | P52: =P51*W51 -> 0 | Q52: =Q51*W51 -> 0 | R52: =R51*W51 -> 0 | S52: =S51*W51 -> 0 | U52: =SUM(O52:T52) -> 0
A54: SET E | H54: =SUM(B54:G54) -> 0 | I54: X | N54: SET E | U54: =SUM(O54:T54) -> 0 | V54: X | X54: =W54*U54 -> 0
A55: total E | H55: =SUM(B55:G55) -> 0 | N55: total E | O55: =O54*W54 -> 0 | P55: =P54*W54 -> 0 | Q55: =Q54*W54 -> 0 | R55: =R54*W54 -> 0 | S55: =S54*W54 -> 0 | U55: =SUM(O55:T55) -> 0
A57: SET F | H57: =SUM(B57:G57) -> 0 | I57: X | N57: SET F | U57: =SUM(O57:T57) -> 0 | V57: X
A58: total F | H58: =SUM(B58:G58) -> 0 | N58: total F | U58: =SUM(O58:T58) -> 0
A60: SET G | H60: =SUM(B60:G60) -> 0 | I60: X | N60: SET G | U60: =SUM(O60:T60) -> 0 | V60: X
A61: total G | H61: =SUM(B61:G61) -> 0 | N61: total G | U61: =SUM(O61:T61) -> 0
A63: SET H | H63: =SUM(B63:G63) -> 0 | I63: X | N63: SET H | U63: =SUM(O63:T63) -> 0 | V63: X
A64: total H | H64: =SUM(B64:G64) -> 0 | N64: total H | U64: =SUM(O64:T64) -> 0
...
