Workbook

Sheet Confirmed PO
A1: PURCHASE ORDER | X1: PT. LARA THALIA ABADI
A2: PO NO | B2: : | L2: EVB | X2: EVERBEST TOWER - CENGKARENG BUSINESS CITY TOWER M
L3: NEW ARRIVAL | X3: Jl. Atang Sanjaya no. 21 Benda - Tangerang Banten, Indonesia
A4: DATE | X4: PHONE : 021 - 2252 9090
A5: TO | B5: : EDE | X5: E-MAIL ADDRESS : buyer@everbestgroup.com
A8: DESCRIPTION | B8: DEVELOP CODE | C8: STYLE NAME | D8: COLOUR | F8: SETS | Y8: QTY CARTON PER 12 | Z8: QTY CARTON PER 8 | AA8: QTY PAIRS | AB8: UNIT PRICE | AC8: AMOUNT
F9: 12A | G9: 12B | H9: 12C | I9: 12D | J9: 12E | K9: 12F | L9: 12G | M9: 8A | N9: 8B | O9: 8C | P9: 8D | Q9: 8E | R9: 6A | S9: 6B | T9: 6C | U9: 6D | V9: 6E | W9: 4A | X9: 4B
B10: 开发代码 | C10: 款式名称 | AB10: US$ | AC10: US$
A11: EVB SHOES - UPPERSTYLE - SUB-UPPERSTYLE | Y11: =SUM(F11:K11)+SUM(R11:V11)/2 -> 0 | Z11: =SUM(M11:Q11)+SUM(W11:X11)/2 -> 0 | AA11: =SUM(E11:K11)*12+SUM(M11:Q11)*8+SUM(R11:V11)*6+SUM(W11:X11)*4 -> 0 | AB11: 0 | AC11: =AB11*AA11 -> 0
Y12: =SUM(F12:K12)+SUM(R12:V12)/2 -> 0 | Z12: =SUM(M12:Q12)+SUM(W12:X12)/2 -> 0 | AA12: =SUM(E12:K12)*12+SUM(M12:Q12)*8+SUM(R12:V12)*6+SUM(W12:X12)*4 -> 0 | AB12: 0 | AC12: =AB12*AA12 -> 0
A13: Material : | Y13: =SUM(F13:K13)+SUM(R13:V13)/2 -> 0 | Z13: =SUM(M13:Q13)+SUM(W13:X13)/2 -> 0 | AA13: =SUM(E13:K13)*12+SUM(M13:Q13)*8+SUM(R13:V13)*6+SUM(W13:X13)*4 -> 0 | AB13: 0 | AC13: =AB13*AA13 -> 0
A14: Lining : | Y14: =SUM(F14:K14)+SUM(R14:V14)/2 -> 0 | Z14: =SUM(M14:Q14)+SUM(W14:X14)/2 -> 0 | AA14: =SUM(E14:K14)*12+SUM(M14:Q14)*8+SUM(R14:V14)*6+SUM(W14:X14)*4 -> 0 | AB14: 0 | AC14: =AB14*AA14 -> 0
A15: Insole :
A16: Outsole :
A17: Heel Height :
Y18: =SUM(Y11:Y17) -> 0 | Z18: =SUM(Z11:Z17) -> 0 | AA18: =SUM(AA11:AA17) -> 0 | AC18: =SUM(AC11:AC17) -> 0
A19: Delivery Date
A20: 交货日期
A21: LOGO : | O21: STYLE NAME | R21: COLOR | T21: SIZES | AA21: TOTAL QTY
A22: 商标 | T22: 35 | U22: =T22+1 -> 36 | V22: =U22+1 -> 37 | W22: =V22+1 -> 38 | X22: =W22+1 -> 39 | Y22: =X22+1 -> 40 | Z22: =Y22+1 -> 41
A23: TERM OF PAYMENT: | B23: CREDIT | O23: =C11 -> 0 | R23: =D11 -> 0 | AA23: =SUM(T23:Z23) -> 0
R24: =D12 -> 0 | AA24: =SUM(T24:Z24) -> 0
A25: CARTON MARK ： | R25: =D13 -> 0 | AA25: =SUM(T25:Z25) -> 0
A26: ( 箱标志 ) | R26: =D14 -> 0 | AA26: =SUM(T26:Z26) -> 0
T27: =SUM(T23:T25) -> 0 | U27: =SUM(U23:U25) -> 0 | V27: =SUM(V23:V25) -> 0 | W27: =SUM(W23:W25) -> 0 | X27: =SUM(X23:X25) -> 0 | Y27: =SUM(Y23:Y25) -> 0 | Z27: =SUM(Z23:Z25) -> 0 | AA27: =SUM(T27:Z27) -> 0
A30: PICTURE ( 图片 ):
A31: =B11 -> 0
A32: =C11 -> 0
A43: =D11 -> 0 | E43: =D12 -> 0 | N43: =D13 -> 0 | W43: =D14 -> 0
A45: SHOE BOX BARCODE : | E45: PACKAGING 包装: | M45: LINING : | S45: SHOE MATERIAL CODE : | Y45: IMPORT LABEL STICKER :
A46: (请贴这些条码在鞋盒按照图片) | E46: (鞋盒 和 箱子 包法) | M46: (打印在内里上） | S46: (鞋子材料贴标) | Y46: (导入标签)
M54: INSOLE 垫脚
A61: USE NEW SHOE BOX DESIGN | E61: PLEASE USE NEW DESIGN OF DUSTBAG AND NEW WRAPPING PAPER | Y61: PLEASE PUT IMPORT LABEL STICKER IN EACH SHOE BOX
A64: Please give us EXTRA TOPLIFT/DIAMOND INSIDE shoesbox, based on the shoes
A65: 請給我們額外的TOPLIFT/DIAMOND 在鞋盒,根據鞋子

Sheet Packing List
A1: ='Confirmed PO'!D11 -> 0
A2: Size | B2: 12A | C2: 12B | D2: 12C | E2: 12D | F2: 12E | G2: 12F | H2: 12G | I2: 8A | J2: 8B | K2: 8C | L2: 8D | M2: 8E | N2: 6A | O2: 6B | P2: 6C | Q2: 6D | R2: 6E | S2: 4A | T2: 4B
A3: 35 | B3: 1 | D3: 1 | E3: 2 | F3: 1 | G3: 2 | I3: 1 | N3: 1
A4: 36 | B4: 2 | C4: 1 | D4: 2 | E4: 2 | F4: 2 | G4: 3 | H4: 2 | I4: 1 | J4: 1 | K4: 1 | L4: 2 | N4: 1 | O4: 1 | P4: 1 | Q4: 1 | S4: 1
A5: 37 | B5: 3 | C5: 2 | D5: 2 | E5: 3 | F5: 3 | G5: 3 | H5: 3 | I5: 2 | J5: 1 | K5: 2 | L5: 2 | M5: 2 | N5: 1 | O5: 1 | P5: 1 | Q5: 2 | R5: 1 | S5: 1 | T5: 1
A6: 38 | B6: 3 | C6: 3 | D6: 3 | E6: 2 | F6: 2 | G6: 2 | H6: 3 | I6: 2 | J6: 2 | K6: 2 | L6: 2 | M6: 2 | N6: 1 | O6: 1 | P6: 2 | Q6: 2 | R6: 2 | S6: 1 | T6: 1
A7: 39 | B7: 2 | C7: 3 | D7: 2 | E7: 2 | F7: 2 | G7: 2 | H7: 2 | I7: 1 | J7: 2 | K7: 2 | L7: 2 | M7: 2 | N7: 1 | O7: 1 | P7: 1 | Q7: 1 | R7: 2 | S7: 1 | T7: 1
A8: 40 | B8: 1 | C8: 2 | D8: 2 | E8: 1 | F8: 1 | H8: 2 | I8: 1 | J8: 1 | K8: 1 | M8: 2 | N8: 1 | O8: 1 | P8: 1 | R8: 1 | T8: 1
A9: 41 | C9: 1 | F9: 1 | J9: 1 | O9: 1
B10: =SUM(B3:B9) -> 12 | C10: =SUM(C3:C9) -> 12 | D10: =SUM(D3:D9) -> 12 | E10: =SUM(E3:E9) -> 12 | F10: =SUM(F3:F9) -> 12 | G10: =SUM(G3:G9) -> 12 | H10: =SUM(H3:H9) -> 12 | I10: =SUM(I3:I9) -> 8 | ... T10: =SUM(T3:T9) -> 4
A12: SET | B12: ='Confirmed PO'!F11 -> 0 | C12: ='Confirmed PO'!G11 -> 0 | D12: ='Confirmed PO'!H11 -> 0 | E12: ='Confirmed PO'!I11 -> 0 | F12: ='Confirmed PO'!J11 -> 0 | G12: ='Confirmed PO'!K11 -> 0 | H12: ='Confirmed PO'!L11 -> 0 | I12: ='Confirmed PO'!M11 -> 0 | ... T12: ='Confirmed PO'!X11 -> 0
A14: 35 | B14: =B3*B$12 -> 0 | C14: =C3*C$12 -> 0 | D14: =D3*D$12 -> 0 | E14: =E3*E$12 -> 0 | F14: =F3*F$12 -> 0 | G14: =G3*G$12 -> 0 | H14: =H3*H$12 -> 0 | I14: =I3*I$12 -> 0 | ... T14: =T3*T$12 -> 0 | U14: =SUM(B14:T14) -> 0
A15: 36 | B15: =B4*B$12 -> 0 | C15: =C4*C$12 -> 0 | D15: =D4*D$12 -> 0 | E15: =E4*E$12 -> 0 | F15: =F4*F$12 -> 0 | G15: =G4*G$12 -> 0 | H15: =H4*H$12 -> 0 | I15: =I4*I$12 -> 0 | ... T15: =T4*T$12 -> 0 | U15: =SUM(B15:T15) -> 0
A16: 37 | B16: =B5*B$12 -> 0 | C16: =C5*C$12 -> 0 | D16: =D5*D$12 -> 0 | E16: =E5*E$12 -> 0 | F16: =F5*F$12 -> 0 | G16: =G5*G$12 -> 0 | H16: =H5*H$12 -> 0 | I16: =I5*I$12 -> 0 | ... T16: =T5*T$12 -> 0 | U16: =SUM(B16:T16) -> 0
A17: 38 | B17: =B6*B$12 -> 0 | C17: =C6*C$12 -> 0 | D17: =D6*D$12 -> 0 | E17: =E6*E$12 -> 0 | F17: =F6*F$12 -> 0 | G17: =G6*G$12 -> 0 | H17: =H6*H$12 -> 0 | I17: =I6*I$12 -> 0 | ... T17: =T6*T$12 -> 0 | U17: =SUM(B17:T17) -> 0
A18: 39 | B18: =B7*B$12 -> 0 | C18: =C7*C$12 -> 0 | D18: =D7*D$12 -> 0 | E18: =E7*E$12 -> 0 | F18: =F7*F$12 -> 0 | G18: =G7*G$12 -> 0 | H18: =H7*H$12 -> 0 | I18: =I7*I$12 -> 0 | ... T18: =T7*T$12 -> 0 | U18: =SUM(B18:T18) -> 0
A19: 40 | B19: =B8*B$12 -> 0 | C19: =C8*C$12 -> 0 | D19: =D8*D$12 -> 0 | E19: =E8*E$12 -> 0 | F19: =F8*F$12 -> 0 | G19: =G8*G$12 -> 0 | H19: =H8*H$12 -> 0 | I19: =I8*I$12 -> 0 | ... T19: =T8*T$12 -> 0 | U19: =SUM(B19:T19) -> 0
A20: 41 | B20: =B9*B$12 -> 0 | C20: =C9*C$12 -> 0 | D20: =D9*D$12 -> 0 | E20: =E9*E$12 -> 0 | F20: =F9*F$12 -> 0 | G20: =G9*G$12 -> 0 | H20: =H9*H$12 -> 0 | I20: =I9*I$12 -> 0 | ... T20: =T9*T$12 -> 0 | U20: =SUM(B20:T20) -> 0
B21: =SUM(B14:B20) -> 0 | C21: =SUM(C14:C20) -> 0 | D21: =SUM(D14:D20) -> 0 | E21: =SUM(E14:E20) -> 0 | F21: =SUM(F14:F20) -> 0 | G21: =SUM(G14:G20) -> 0 | H21: =SUM(H14:H20) -> 0 | I21: =SUM(I14:I20) -> 0 | ... T21: =SUM(T14:T20) -> 0 | U21: =SUM(B21:T21) -> 0
A24: ='Confirmed PO'!D12 -> 0
A25: Size | B25: 12A | C25: 12B | D25: 12C | E25: 12D | F25: 12E | G25: 12F | H25: 12G | I25: 8A | J25: 8B | K25: 8C | L25: 8D | M25: 8E | N25: 6A | O25: 6B | P25: 6C | Q25: 6D | R25: 6E | S25: 4A | T25: 4B
A26: 35 | B26: 1 | D26: 1 | E26: 2 | F26: 1 | G26: 2 | I26: 1 | N26: 1
A27: 36 | B27: 2 | C27: 1 | D27: 2 | E27: 2 | F27: 2 | G27: 3 | H27: 2 | I27: 1 | J27: 1 | K27: 1 | L27: 2 | N27: 1 | O27: 1 | P27: 1 | Q27: 1 | S27: 1
A28: 37 | B28: 3 | C28: 2 | D28: 2 | E28: 3 | F28: 3 | G28: 3 | H28: 3 | I28: 2 | J28: 1 | K28: 2 | L28: 2 | M28: 2 | N28: 1 | O28: 1 | P28: 1 | Q28: 2 | R28: 1 | S28: 1 | T28: 1
A29: 38 | B29: 3 | C29: 3 | D29: 3 | E29: 2 | F29: 2 | G29: 2 | H29: 3 | I29: 2 | J29: 2 | K29: 2 | L29: 2 | M29: 2 | N29: 1 | O29: 1 | P29: 2 | Q29: 2 | R29: 2 | S29: 1 | T29: 1
A30: 39 | B30: 2 | C30: 3 | D30: 2 | E30: 2 | F30: 2 | G30: 2 | H30: 2 | I30: 1 | J30: 2 | K30: 2 | L30: 2 | M30: 2 | N30: 1 | O30: 1 | P30: 1 | Q30: 1 | R30: 2 | S30: 1 | T30: 1
A31: 40 | B31: 1 | C31: 2 | D31: 2 | E31: 1 | F31: 1 | H31: 2 | I31: 1 | J31: 1 | K31: 1 | M31: 2 | N31: 1 | O31: 1 | P31: 1 | R31: 1 | T31: 1
A32: 41 | C32: 1 | F32: 1 | J32: 1 | O32: 1
B33: =SUM(B26:B32) -> 12 | C33: =SUM(C26:C32) -> 12 | D33: =SUM(D26:D32) -> 12 | E33: =SUM(E26:E32) -> 12 | F33: =SUM(F26:F32) -> 12 | G33: =SUM(G26:G32) -> 12 | H33: =SUM(H26:H32) -> 12 | I33: =SUM(I26:I32) -> 8 | ... T33: =SUM(T26:T32) -> 4
A35: SET | B35: ='Confirmed PO'!F12 -> 0 | C35: ='Confirmed PO'!G12 -> 0 | D35: ='Confirmed PO'!H12 -> 0 | E35: ='Confirmed PO'!I12 -> 0 | F35: ='Confirmed PO'!J12 -> 0 | G35: ='Confirmed PO'!K12 -> 0 | H35: ='Confirmed PO'!L12 -> 0 | I35: ='Confirmed PO'!M12 -> 0 | ... T35: ='Confirmed PO'!X12 -> 0
A37: 35 | B37: =B26*B$35 -> 0 | C37: =C26*C$35 -> 0 | D37: =D26*D$35 -> 0 | E37: =E26*E$35 -> 0 | F37: =F26*F$35 -> 0 | G37: =G26*G$35 -> 0 | H37: =H26*H$35 -> 0 | I37: =I26*I$35 -> 0 | ... T37: =T26*T$35 -> 0 | U37: =SUM(B37:T37) -> 0
A38: 36 | B38: =B27*B$35 -> 0 | C38: =C27*C$35 -> 0 | D38: =D27*D$35 -> 0 | E38: =E27*E$35 -> 0 | F38: =F27*F$35 -> 0 | G38: =G27*G$35 -> 0 | H38: =H27*H$35 -> 0 | I38: =I27*I$35 -> 0 | ... T38: =T27*T$35 -> 0 | U38: =SUM(B38:T38) -> 0
A39: 37 | B39: =B28*B$35 -> 0 | C39: =C28*C$35 -> 0 | D39: =D28*D$35 -> 0 | E39: =E28*E$35 -> 0 | F39: =F28*F$35 -> 0 | G39: =G28*G$35 -> 0 | H39: =H28*H$35 -> 0 | I39: =I28*I$35 -> 0 | ... T39: =T28*T$35 -> 0 | U39: =SUM(B39:T39) -> 0
A40: 38 | B40: =B29*B$35 -> 0 | C40: =C29*C$35 -> 0 | D40: =D29*D$35 -> 0 | E40: =E29*E$35 -> 0 | F40: =F29*F$35 -> 0 | G40: =G29*G$35 -> 0 | H40: =H29*H$35 -> 0 | I40: =I29*I$35 -> 0 | ... T40: =T29*T$35 -> 0 | U40: =SUM(B40:T40) -> 0
A41: 39 | B41: =B30*B$35 -> 0 | C41: =C30*C$35 -> 0 | D41: =D30*D$35 -> 0 | E41: =E30*E$35 -> 0 | F41: =F30*F$35 -> 0 | G41: =G30*G$35 -> 0 | H41: =H30*H$35 -> 0 | I41: =I30*I$35 -> 0 | ... T41: =T30*T$35 -> 0 | U41: =SUM(B41:T41) -> 0
A42: 40 | B42: =B31*B$35 -> 0 | C42: =C31*C$35 -> 0 | D42: =D31*D$35 -> 0 | E42: =E31*E$35 -> 0 | F42: =F31*F$35 -> 0 | G42: =G31*G$35 -> 0 | H42: =H31*H$35 -> 0 | I42: =I31*I$35 -> 0 | ... T42: =T31*T$35 -> 0 | U42: =SUM(B42:T42) -> 0
A43: 41 | B43: =B32*B$35 -> 0 | C43: =C32*C$35 -> 0 | D43: =D32*D$35 -> 0 | E43: =E32*E$35 -> 0 | F43: =F32*F$35 -> 0 | G43: =G32*G$35 -> 0 | H43: =H32*H$35 -> 0 | I43: =I32*I$35 -> 0 | ... T43: =T32*T$35 -> 0 | U43: =SUM(B43:T43) -> 0
B44: =SUM(B37:B43) -> 0 | C44: =SUM(C37:C43) -> 0 | D44: =SUM(D37:D43) -> 0 | E44: =SUM(E37:E43) -> 0 | F44: =SUM(F37:F43) -> 0 | G44: =SUM(G37:G43) -> 0 | H44: =SUM(H37:H43) -> 0 | I44: =SUM(I37:I43) -> 0 | ... T44: =SUM(T37:T43) -> 0 | U44: =SUM(B44:T44) -> 0
A47: ='Confirmed PO'!D13 -> 0
A48: Size | B48: 12A | C48: 12B | D48: 12C | E48: 12D | F48: 12E | G48: 12F | H48: 12G | I48: 8A | J48: 8B | K48: 8C | L48: 8D | M48: 8E | N48: 6A | O48: 6B | P48: 6C | Q48: 6D | R48: 6E | S48: 4A | T48: 4B
...
