Workbook

Sheet Confirmed PO
A1: PURCHASE ORDER | K1: PT. LARA THALIA ABADI
A2: PO NO | B2: : 10422 | K2: EVERBEST TOWER - CENGKARENG BUSINESS CITY TOWER M
E3: EVERBEST | K3: Jl. Atang Sanjaya no. 21 Benda - Tangerang Banten, Indonesia
A4: DATE | B4: : 12 Aug 2026 | E4: NEW ARRIVAL | K4: PHONE : 021 - 2252 9090
A5: TO | B5: : EDE | E5: JAKARTA | K5: E-MAIL ADDRESS : buyer@everbestgroup.com
E6: WINTER 2026
A8: DESCRIPTION | B8: DEVELOP CODE | C8: STYLE NAME | D8: COLOUR | E8: SETS | X8: QTY CARTON PER 12 | Y8: QTY CARTON PER 8 | Z8: QTY PAIRS | AA8: UNIT PRICE | AB8: AMOUNT
E9: 12A | F9: 12B | G9: 12C | H9: 12E | I9: 12F | J9: 12H | K9: 12J | L9: 12L | M9: 4A | N9: 4B | O9: 4C | P9: 6A | Q9: 6B | R9: 6C | S9: 6D | T9: 8D | U9: 8I | V9: 8K | W9: 8L
B10: 开发代码 | C10: 款式名称 | AA10: US$ | AB10: US$
A11: EVERBEST MEN SHOES - BOOT | B11: 264EB133 | C11: NOAM | D11: CHOCOLATE | E11: 0 | F11: 0 | G11: 0 | H11: 0 | I11: 0 | J11: 0 | K11: 0 | L11: 0 | M11: 0 | N11: 0 | O11: 0 | P11: 4 | Q11: 6 | R11: 4 | S11: 0 | T11: 0 | U11: 0 | V11: 0 | W11: 0 | X11: =SUM(E11:L11)+SUM(P11:S11)/2 -> 7 | Y11: =SUM(T11:W11)+SUM(M11:O11)/2 -> 0 | Z11: =(X11*12)+(Y11*8) -> 84 | AA11: 52.06 | AB11: =Z11*AA11 -> 4373.04
D12: GRAPHITE_BLACK | E12: 0 | F12: 0 | G12: 0 | H12: 0 | I12: 0 | J12: 0 | K12: 0 | L12: 0 | M12: 0 | N12: 0 | O12: 0 | P12: 4 | Q12: 6 | R12: 4 | S12: 0 | T12: 0 | U12: 0 | V12: 0 | W12: 0 | X12: =SUM(E12:L12)+SUM(P12:S12)/2 -> 7 | Y12: =SUM(T12:W12)+SUM(M12:O12)/2 -> 0 | Z12: =(X12*12)+(Y12*8) -> 84 | AA12: 52.06 | AB12: =Z12*AA12 -> 4373.04
A13: Upper : LEATHER | X13: =SUM(E13:L13)+SUM(P13:S13)/2 -> 0 | Y13: =SUM(T13:W13)+SUM(M13:O13)/2 -> 0 | Z13: =(X13*12)+(Y13*8) -> 0 | AB13: =Z13*AA13 -> 0
A14: Lining : LEATHER | X14: =SUM(E14:L14)+SUM(P14:S14)/2 -> 0 | Y14: =SUM(T14:W14)+SUM(M14:O14)/2 -> 0 | Z14: =(X14*12)+(Y14*8) -> 0 | AB14: =Z14*AA14 -> 0
A15: Insole : LEATHER+MICROFIBER | AB15: =Z15*AA15 -> 0
A16: Outsole : RUBBER | AB16: =Z16*AA16 -> 0
A17: Heel Height : < 3 CM | AB17: =Z17*AA17 -> 0
X18: =SUM(X11:X17) -> 14 | Y18: =SUM(Y11:Y17) -> 0 | Z18: =SUM(Z11:Z17) -> 168 | AB18: =SUM(AB11:AB14) -> 8746.08
A19: Delivery Date | B19: 46307
A20: 交货日期
A21: LOGO : | F21: COLOR | G21: 39 | H21: 40 | I21: 41 | J21: 42 | K21: 43 | L21: 44 | M21: 45 | N21: 46 | O21: TOTAL
A22: 商标 | F22: =D11 -> CHOCOLATE | G22: 8 | H22: 14 | I22: 18 | J22: 20 | K22: 14 | L22: 10 | O22: =SUM(G22:M22) -> 84
A23: TERM OF PAYMENT: | B23: CREDIT | F23: =D12 -> GRAPHITE_BLACK | G23: 8 | H23: 14 | I23: 18 | J23: 20 | K23: 14 | L23: 10 | O23: =SUM(G23:M23) -> 84
F24: =D13 -> 0 | O24: =SUM(G24:M24) -> 0
A25: CARTON MARK ： | F25: =D14 -> 0 | O25: =SUM(G25:M25) -> 0
A26: ( 箱标志 )
F27: TOTAL | O27: =SUM(O22:O26) -> 168
A29: PICTURE ( 图片 ):
A30: =B11 -> 264EB133
A31: =C11 -> NOAM
A37: CHOCOLATE | C37: GRAPHITE_BLACK
A38: =D11 -> CHOCOLATE | C38: =D12 -> GRAPHITE_BLACK | E38: =D13 -> 0 | G38: =D14 -> 0
A39: SHOE BOX BARCODE : | C39: PACKAGING 包装: | F39: QR CODE STICKER: | N39: LINING | T39: SHOE MATERIAL CODE
A40: (请贴这些条码在鞋盒按照图片) | C40: 鞋盒 和 箱子 包法 | F40: 二维码贴纸: | N40: (打印在内里上） | T40: 鞋子材料贴标
N41: INSOLE 垫脚
A53: 1. USING NEW SHOES BOX DESIGN | C53: 1. PLEASE USE NEW DESIGN OF DUSTBAG AND NEW WRAPPING PAPER | F53: 2. PLEASE PUT QR CODE STICKER IN EACH SHOE BOX | N53: USE NEW LOGO AND LEATHER LOGO | T53: PUT STICKERS AS SHOES COMPOSITION MATERIAL
A54: 2. LADIES SHOES BOX USING RED EYELET
A55: 3. MENS SHOES BOX USING BEIGE EYELET

Sheet Packing List
A1: ='Confirmed PO'!D11 -> CHOCOLATE
A2: Size | B2: 12A | C2: 12B | D2: 12C | E2: 12E | F2: 12F | G2: 12H | H2: 12J | I2: 12L | J2: 4A | K2: 4B | L2: 4C | M2: 6A | N2: 6B | O2: 6C | P2: 6D | Q2: 8D | R2: 8I | S2: 8K | T2: 8L
A3: 39 | B3: 1 | C3: 1 | D3: 2 | E3: 1 | F3: 1 | G3: 3 | I3: 1 | J3: 1 | M3: 1 | O3: 1 | Q3: 1 | R3: 1
A4: 40 | B4: 2 | C4: 2 | D4: 2 | E4: 2 | F4: 2 | G4: 3 | H4: 2 | I4: 2 | J4: 1 | K4: 1 | M4: 1 | N4: 1 | O4: 1 | P4: 1 | Q4: 2 | R4: 1 | S4: 2 | T4: 1
A5: 41 | B5: 3 | C5: 2 | D5: 3 | E5: 2 | F5: 3 | G5: 3 | H5: 4 | I5: 2 | J5: 1 | K5: 1 | L5: 1 | M5: 2 | N5: 1 | O5: 1 | P5: 1 | Q5: 2 | R5: 2 | S5: 2 | T5: 1
A6: 42 | B6: 3 | C6: 3 | D6: 2 | E6: 2 | F6: 2 | G6: 3 | H6: 4 | I6: 3 | J6: 1 | K6: 1 | L6: 1 | M6: 1 | N6: 2 | O6: 1 | P6: 1 | Q6: 2 | R6: 2 | S6: 2 | T6: 2
A7: 43 | B7: 2 | C7: 2 | D7: 2 | E7: 2 | F7: 2 | H7: 2 | I7: 2 | K7: 1 | L7: 1 | M7: 1 | N7: 1 | O7: 1 | P7: 1 | Q7: 1 | R7: 1 | S7: 2 | T7: 2
A8: 44 | B8: 1 | C8: 2 | D8: 1 | E8: 2 | F8: 1 | I8: 1 | L8: 1 | N8: 1 | O8: 1 | P8: 1 | R8: 1 | T8: 1
A9: 45 | E9: 1 | F9: 1 | I9: 1 | P9: 1 | T9: 1
A10: 46
B11: 12 | C11: 12 | D11: 12 | E11: 12 | F11: 12 | G11: 12 | H11: 12 | I11: 12 | J11: 4 | K11: 4 | L11: 4 | M11: 6 | N11: 6 | O11: 6 | P11: 6 | Q11: 8 | R11: 8 | S11: 8 | T11: 8
A13: SET | B13: ='Confirmed PO'!E11 -> 0 | C13: ='Confirmed PO'!F11 -> 0 | D13: ='Confirmed PO'!G11 -> 0 | E13: ='Confirmed PO'!H11 -> 0 | F13: ='Confirmed PO'!I11 -> 0 | G13: ='Confirmed PO'!J11 -> 0 | H13: ='Confirmed PO'!K11 -> 0 | I13: ='Confirmed PO'!L11 -> 0 | ... T13: ='Confirmed PO'!W11 -> 0
A15: 39 | B15: =B3*B$13 -> 0 | C15: =C3*C$13 -> 0 | D15: =D3*D$13 -> 0 | E15: =E3*E$13 -> 0 | F15: =F3*F$13 -> 0 | G15: =G3*G$13 -> 0 | H15: =H3*H$13 -> 0 | I15: =I3*I$13 -> 0 | ... T15: =T3*T$13 -> 0 | U15: =SUM(B15:T15) -> 8
A16: 40 | B16: =B4*B$13 -> 0 | C16: =C4*C$13 -> 0 | D16: =D4*D$13 -> 0 | E16: =E4*E$13 -> 0 | F16: =F4*F$13 -> 0 | G16: =G4*G$13 -> 0 | H16: =H4*H$13 -> 0 | I16: =I4*I$13 -> 0 | ... T16: =T4*T$13 -> 0 | U16: =SUM(B16:T16) -> 14
A17: 41 | B17: =B5*B$13 -> 0 | C17: =C5*C$13 -> 0 | D17: =D5*D$13 -> 0 | E17: =E5*E$13 -> 0 | F17: =F5*F$13 -> 0 | G17: =G5*G$13 -> 0 | H17: =H5*H$13 -> 0 | I17: =I5*I$13 -> 0 | ... T17: =T5*T$13 -> 0 | U17: =SUM(B17:T17) -> 18
A18: 42 | B18: =B6*B$13 -> 0 | C18: =C6*C$13 -> 0 | D18: =D6*D$13 -> 0 | E18: =E6*E$13 -> 0 | F18: =F6*F$13 -> 0 | G18: =G6*G$13 -> 0 | H18: =H6*H$13 -> 0 | I18: =I6*I$13 -> 0 | ... T18: =T6*T$13 -> 0 | U18: =SUM(B18:T18) -> 20
A19: 43 | B19: =B7*B$13 -> 0 | C19: =C7*C$13 -> 0 | D19: =D7*D$13 -> 0 | E19: =E7*E$13 -> 0 | F19: =F7*F$13 -> 0 | G19: =G7*G$13 -> 0 | H19: =H7*H$13 -> 0 | I19: =I7*I$13 -> 0 | ... T19: =T7*T$13 -> 0 | U19: =SUM(B19:T19) -> 14
A20: 44 | B20: =B8*B$13 -> 0 | C20: =C8*C$13 -> 0 | D20: =D8*D$13 -> 0 | E20: =E8*E$13 -> 0 | F20: =F8*F$13 -> 0 | G20: =G8*G$13 -> 0 | H20: =H8*H$13 -> 0 | I20: =I8*I$13 -> 0 | ... T20: =T8*T$13 -> 0 | U20: =SUM(B20:T20) -> 10
A21: 45 | B21: =B9*B$13 -> 0 | C21: =C9*C$13 -> 0 | D21: =D9*D$13 -> 0 | E21: =E9*E$13 -> 0 | F21: =F9*F$13 -> 0 | G21: =G9*G$13 -> 0 | H21: =H9*H$13 -> 0 | I21: =I9*I$13 -> 0 | ... T21: =T9*T$13 -> 0 | U21: =SUM(B21:T21) -> 0
A22: 46 | B22: =B10*B$13 -> 0 | C22: =C10*C$13 -> 0 | D22: =D10*D$13 -> 0 | E22: =E10*E$13 -> 0 | F22: =F10*F$13 -> 0 | G22: =G10*G$13 -> 0 | H22: =H10*H$13 -> 0 | I22: =I10*I$13 -> 0 | ... T22: =T10*T$13 -> 0 | U22: =SUM(B22:T22) -> 0
B23: =B11*B$13 -> 0 | C23: =C11*C$13 -> 0 | D23: =D11*D$13 -> 0 | E23: =E11*E$13 -> 0 | F23: =F11*F$13 -> 0 | G23: =G11*G$13 -> 0 | H23: =H11*H$13 -> 0 | I23: =I11*I$13 -> 0 | ... T23: =T11*T$13 -> 0 | U23: =SUM(B23:T23) -> 84
A25: ='Confirmed PO'!D12 -> GRAPHITE_BLACK
A26: Size | B26: 12A | C26: 12B | D26: 12C | E26: 12E | F26: 12F | G26: 12H | H26: 12J | I26: 12L | J26: 4A | K26: 4B | L26: 4C | M26: 6A | N26: 6B | O26: 6C | P26: 6D | Q26: 8D | R26: 8I | S26: 8K | T26: 8L
A27: 39 | B27: 1 | C27: 1 | D27: 2 | E27: 1 | F27: 1 | G27: 3 | I27: 1 | J27: 1 | M27: 1 | O27: 1 | Q27: 1 | R27: 1
A28: 40 | B28: 2 | C28: 2 | D28: 2 | E28: 2 | F28: 2 | G28: 3 | H28: 2 | I28: 2 | J28: 1 | K28: 1 | M28: 1 | N28: 1 | O28: 1 | P28: 1 | Q28: 2 | R28: 1 | S28: 2 | T28: 1
A29: 41 | B29: 3 | C29: 2 | D29: 3 | E29: 2 | F29: 3 | G29: 3 | H29: 4 | I29: 2 | J29: 1 | K29: 1 | L29: 1 | M29: 2 | N29: 1 | O29: 1 | P29: 1 | Q29: 2 | R29: 2 | S29: 2 | T29: 1
A30: 42 | B30: 3 | C30: 3 | D30: 2 | E30: 2 | F30: 2 | G30: 3 | H30: 4 | I30: 3 | J30: 1 | K30: 1 | L30: 1 | M30: 1 | N30: 2 | O30: 1 | P30: 1 | Q30: 2 | R30: 2 | S30: 2 | T30: 2
A31: 43 | B31: 2 | C31: 2 | D31: 2 | E31: 2 | F31: 2 | H31: 2 | I31: 2 | K31: 1 | L31: 1 | M31: 1 | N31: 1 | O31: 1 | P31: 1 | Q31: 1 | R31: 1 | S31: 2 | T31: 2
A32: 44 | B32: 1 | C32: 2 | D32: 1 | E32: 2 | F32: 1 | I32: 1 | L32: 1 | N32: 1 | O32: 1 | P32: 1 | R32: 1 | T32: 1
A33: 45 | E33: 1 | F33: 1 | I33: 1 | P33: 1 | T33: 1
A34: 46
B35: 12 | C35: 12 | D35: 12 | E35: 12 | F35: 12 | G35: 12 | H35: 12 | I35: 12 | J35: 4 | K35: 4 | L35: 4 | M35: 6 | N35: 6 | O35: 6 | P35: 6 | Q35: 8 | R35: 8 | S35: 8 | T35: 8
A37: SET | B37: ='Confirmed PO'!E12 -> 0 | C37: ='Confirmed PO'!F12 -> 0 | D37: ='Confirmed PO'!G12 -> 0 | E37: ='Confirmed PO'!H12 -> 0 | F37: ='Confirmed PO'!I12 -> 0 | G37: ='Confirmed PO'!J12 -> 0 | H37: ='Confirmed PO'!K12 -> 0 | I37: ='Confirmed PO'!L12 -> 0 | ... T37: ='Confirmed PO'!W12 -> 0
A39: 39 | B39: =B27*B$37 -> 0 | C39: =C27*C$37 -> 0 | D39: =D27*D$37 -> 0 | E39: =E27*E$37 -> 0 | F39: =F27*F$37 -> 0 | G39: =G27*G$37 -> 0 | H39: =H27*H$37 -> 0 | I39: =I27*I$37 -> 0 | ... T39: =T27*T$37 -> 0 | U39: =SUM(B39:T39) -> 8
A40: 40 | B40: =B28*B$37 -> 0 | C40: =C28*C$37 -> 0 | D40: =D28*D$37 -> 0 | E40: =E28*E$37 -> 0 | F40: =F28*F$37 -> 0 | G40: =G28*G$37 -> 0 | H40: =H28*H$37 -> 0 | I40: =I28*I$37 -> 0 | ... T40: =T28*T$37 -> 0 | U40: =SUM(B40:T40) -> 14
A41: 41 | B41: =B29*B$37 -> 0 | C41: =C29*C$37 -> 0 | D41: =D29*D$37 -> 0 | E41: =E29*E$37 -> 0 | F41: =F29*F$37 -> 0 | G41: =G29*G$37 -> 0 | H41: =H29*H$37 -> 0 | I41: =I29*I$37 -> 0 | ... T41: =T29*T$37 -> 0 | U41: =SUM(B41:T41) -> 18
A42: 42 | B42: =B30*B$37 -> 0 | C42: =C30*C$37 -> 0 | D42: =D30*D$37 -> 0 | E42: =E30*E$37 -> 0 | F42: =F30*F$37 -> 0 | G42: =G30*G$37 -> 0 | H42: =H30*H$37 -> 0 | I42: =I30*I$37 -> 0 | ... T42: =T30*T$37 -> 0 | U42: =SUM(B42:T42) -> 20
A43: 43 | B43: =B31*B$37 -> 0 | C43: =C31*C$37 -> 0 | D43: =D31*D$37 -> 0 | E43: =E31*E$37 -> 0 | F43: =F31*F$37 -> 0 | G43: =G31*G$37 -> 0 | H43: =H31*H$37 -> 0 | I43: =I31*I$37 -> 0 | ... T43: =T31*T$37 -> 0 | U43: =SUM(B43:T43) -> 14
A44: 44 | B44: =B32*B$37 -> 0 | C44: =C32*C$37 -> 0 | D44: =D32*D$37 -> 0 | E44: =E32*E$37 -> 0 | F44: =F32*F$37 -> 0 | G44: =G32*G$37 -> 0 | H44: =H32*H$37 -> 0 | I44: =I32*I$37 -> 0 | ... T44: =T32*T$37 -> 0 | U44: =SUM(B44:T44) -> 10
A45: 45 | B45: =B33*B$37 -> 0 | C45: =C33*C$37 -> 0 | D45: =D33*D$37 -> 0 | E45: =E33*E$37 -> 0 | F45: =F33*F$37 -> 0 | G45: =G33*G$37 -> 0 | H45: =H33*H$37 -> 0 | I45: =I33*I$37 -> 0 | ... T45: =T33*T$37 -> 0 | U45: =SUM(B45:T45) -> 0
...
